Workbook
Name airvendorbuyer: #REF!

Sheet 整车装载能力
B2: 装载能力
B3: 干货与危险品卡车
B4: 设备类型 | C4: 实际装载能力
B5: 3T | C5: 12
B6: 5T | C6: 23
B7: 8T | C7: 32
B8: 10T | C8: 40
B9: 12T | C9: 45
B10: 15T | C10: 55
B11: 25T | C11: 90
B12: 26T | C12: 110
B13: 30T | C13: 145
B14: 20尺集装箱 | C14: 28
B15: 40尺集装箱 | C15: 58
B16: 40尺高柜集装箱 | C16: 68

Sheet 整车费率
B1: 整车费率
B2: 费率由运输部（MOT）审定。所报费率不得以捆绑中标为条件。
B4: 目的地
B5: SHDR DC1（主配送中心）：上海临港新城普洛斯临港物流园洋浩路575号，中国上海市浦东新区
B6: TDSC 配送中心：上海市奉贤区航塘公路3088号C栋3楼迪士尼商店仓库，开瑞益上海配送中心C3，上海市奉贤区航塘公路3088号
B7: 币种：人民币 | C7: 不含增值税
F9: SHDR DC1/TDSC DC | M9: SHDR DC1/TDSC DC
B10: 出发省份 | C10: 出发城市 | D10: 车型 | E10: 温度类型 | F10: 运输天数（不含提货日） | G10: 费率（人民币）不含增值税 | H10: 出发省份 | I10: 出发城市 | J10: 车型 | K10: 温度类型 | M10: 运输天数（不含提货日） | N10: 费率（人民币）不含增值税 | P10: 附加费说明 | Q10: 每次附加费（人民币）
B11: 安徽 | C11: 巢湖 | D11: 10T | E11: 干货 | F11: 1 | G11: 3060 | H11: =VLOOKUP(B11,Sheet1!A:B,2,0) -> Anhui | I11: =VLOOKUP(C11,Sheet1!C:D,2,0) -> Chaohu | J11: 10T | K11: DRY | L11: AnhuiChaohu10TDRY | O11: 1350 | P11: 停车费（¥）
B12: 安徽 | C12: 巢湖 | D12: 12T | E12: 干货 | F12: 1 | G12: 3120 | H12: =VLOOKUP(B12,Sheet1!A:B,2,0) -> Anhui | I12: =VLOOKUP(C12,Sheet1!C:D,2,0) -> Chaohu | J12: 12T | K12: DRY | L12: AnhuiChaohu12TDRY | P12: 理货费（¥）*
B13: 安徽 | C13: 巢湖 | D13: 15T | E13: 干货 | F13: 1 | G13: 4776 | H13: =VLOOKUP(B13,Sheet1!A:B,2,0) -> Anhui | I13: =VLOOKUP(C13,Sheet1!C:D,2,0) -> Chaohu | J13: 15T | K13: DRY | L13: AnhuiChaohu15TDRY | P13: 危险品费（¥）
B14: 安徽 | C14: 巢湖 | D14: 26T | E14: 干货 | F14: 1 | G14: 5028 | H14: =VLOOKUP(B14,Sheet1!A:B,2,0) -> Anhui | I14: =VLOOKUP(C14,Sheet1!C:D,2,0) -> Chaohu | J14: 26T | K14: DRY | L14: AnhuiChaohu26TDRY | P14: 空驶费（已派车未使用）（¥）
B15: 安徽 | C15: 巢湖 | D15: 3T | E15: 干货 | F15: 1 | G15: 1620 | H15: =VLOOKUP(B15,Sheet1!A:B,2,0) -> Anhui | I15: =VLOOKUP(C15,Sheet1!C:D,2,0) -> Chaohu | J15: 3T | K15: DRY | L15: AnhuiChaohu3TDRY
B16: 安徽 | C16: 巢湖 | D16: 5T | E16: 干货 | F16: 1 | G16: 2640 | H16: =VLOOKUP(B16,Sheet1!A:B,2,0) -> Anhui | I16: =VLOOKUP(C16,Sheet1!C:D,2,0) -> Chaohu | J16: 5T | K16: DRY | L16: AnhuiChaohu5TDRY
B17: 安徽 | C17: 巢湖 | D17: 8T | E17: 干货 | F17: 1 | G17: 2520 | H17: =VLOOKUP(B17,Sheet1!A:B,2,0) -> Anhui | I17: =VLOOKUP(C17,Sheet1!C:D,2,0) -> Chaohu | J17: 8T | K17: DRY | L17: AnhuiChaohu8TDRY
B18: 安徽 | C18: 巢湖 | D18: 40尺高柜 | E18: 干货 - 自备箱 | F18: 1 | G18: 5040 | H18: =VLOOKUP(B18,Sheet1!A:B,2,0) -> Anhui | I18: =VLOOKUP(C18,Sheet1!C:D,2,0) -> Chaohu | J18: 40'HQ | K18: DRY - SOC | L18: AnhuiChaohu40'HQDRY - SOC
B19: 安徽 | C19: 天长 | D19: 10T | E19: 干货 | F19: 1 | G19: 2760 | H19: =VLOOKUP(B19,Sheet1!A:B,2,0) -> Anhui | I19: =VLOOKUP(C19,Sheet1!C:D,2,0) -> Tianchang | J19: 10T | K19: DRY | L19: AnhuiTianchang10TDRY
B20: 安徽 | C20: 天长 | D20: 12T | E20: 干货 | F20: 1 | G20: 2760 | H20: =VLOOKUP(B20,Sheet1!A:B,2,0) -> Anhui | I20: =VLOOKUP(C20,Sheet1!C:D,2,0) -> Tianchang | J20: 12T | K20: DRY | L20: AnhuiTianchang12TDRY
B21: 安徽 | C21: 天长 | D21: 15T | E21: 干货 | F21: 1 | G21: 4284 | H21: =VLOOKUP(B21,Sheet1!A:B,2,0) -> Anhui | I21: =VLOOKUP(C21,Sheet1!C:D,2,0) -> Tianchang | J21: 15T | K21: DRY | L21: AnhuiTianchang15TDRY
B22: 安徽 | C22: 天长 | D22: 25T | E22: 干货 | F22: 1 | G22: 4740 | H22: =VLOOKUP(B22,Sheet1!A:B,2,0) -> Anhui | I22: =VLOOKUP(C22,Sheet1!C:D,2,0) -> Tianchang | J22: 25T | K22: DRY | L22: AnhuiTianchang25TDRY
B23: 安徽 | C23: 天长 | D23: 26T | E23: 干货 | F23: 1 | G23: 4980 | H23: =VLOOKUP(B23,Sheet1!A:B,2,0) -> Anhui | I23: =VLOOKUP(C23,Sheet1!C:D,2,0) -> Tianchang | J23: 26T | K23: DRY | L23: AnhuiTianchang26TDRY
B24: 安徽 | C24: 天长 | D24: 3T | E24: 干货 | F24: 1 | G24: 1380 | H24: =VLOOKUP(B24,Sheet1!A:B,2,0) -> Anhui | I24: =VLOOKUP(C24,Sheet1!C:D,2,0) -> Tianchang | J24: 3T | K24: DRY | L24: AnhuiTianchang3TDRY
B25: 安徽 | C25: 天长 | D25: 5T | E25: 干货 | F25: 1 | G25: 2400 | H25: =VLOOKUP(B25,Sheet1!A:B,2,0) -> Anhui | I25: =VLOOKUP(C25,Sheet1!C:D,2,0) -> Tianchang | J25: 5T | K25: DRY | L25: AnhuiTianchang5TDRY
B26: 安徽 | C26: 天长 | D26: 8T | E26: 干货 | F26: 1 | G26: 2460 | H26: =VLOOKUP(B26,Sheet1!A:B,2,0) -> Anhui | I26: =VLOOKUP(C26,Sheet1!C:D,2,0) -> Tianchang | J26: 8T | K26: DRY | L26: AnhuiTianchang8TDRY
... B49: 广东 | C49: 东莞 | D49: 8T | E49: 干货 | F49: 3 | G49: 5280 | H49: =VLOOKUP(B49,Sheet1!A:B,2,0) -> Guangdong | I49: =VLOOKUP(C49,Sheet1!C:D,2,0) -> Dongguan | J49: 8T | K49: DRY | L49: GuangdongDongguan8TDRY
B50: 广东 | C50: 东莞 | D50: DG_3T | E50: 危险品 | H50: =VLOOKUP(B50,Sheet1!A:B,2,0) -> Guangdong | I50: =VLOOKUP(C50,Sheet1!C:D,2,0) -> Dongguan | J50: DG_3T | K50: HAZMAT | L50: GuangdongDongguanDG_3THAZMAT
B51: 广东 | C51: 东莞 | D51: DG_8T | E51: 危险品 | H51: =VLOOKUP(B51,Sheet1!A:B,2,0) -> Guangdong | I51: =VLOOKUP(C51,Sheet1!C:D,2,0) -> Dongguan | J51: DG_8T | K51: HAZMAT | L51: GuangdongDongguanDG_8THAZMAT
B52: 广东 | C52: 东莞 | D52: REF_3T | E52: 冷藏 | H52: =VLOOKUP(B52,Sheet1!A:B,2,0) -> Guangdong | I52: =VLOOKUP(C52,Sheet1!C:D,2,0) -> Dongguan | J52: REF_3T | K52: REEFER | L52: GuangdongDongguanREF_3TREEFER
B53: 广东 | C53: 东莞 | D53: 40尺高柜 | E53: 干货 - 自备箱 | F53: 3 | G53: 8200 | H53: =VLOOKUP(B53,Sheet1!A:B,2,0) -> Guangdong | I53: =VLOOKUP(C53,Sheet1!C:D,2,0) -> Dongguan | J53: 40'HQ | K53: DRY - SOC | L53: GuangdongDongguan40'HQDRY - SOC
B54: 广东 | C54: 佛山 | D54: 3T | E54: 干货 | F54: 3 | G54: 3600 | H54: =VLOOKUP(B54,Sheet1!A:B,2,0) -> Guangdong | I54: =VLOOKUP(C54,Sheet1!C:D,2,0) -> Foshan | J54: 3T | K54: DRY | L54: GuangdongFoshan3TDRY
B55: 广东 | C55: 佛山 | D55: 5T | E55: 干货 | F55: 3 | G55: 4440 | H55: =VLOOKUP(B55,Sheet1!A:B,2,0) -> Guangdong | I55: =VLOOKUP(C55,Sheet1!C:D,2,0) -> Foshan | J55: 5T | K55: DRY | L55: GuangdongFoshan5TDRY
B56: 广东 | C56: 佛山 | D56: REF_3T | E56: 冷藏 | H56: =VLOOKUP(B56,Sheet1!A:B,2,0) -> Guangdong | I56: =VLOOKUP(C56,Sheet1!C:D,2,0) -> Foshan | J56: REF_3T | K56: REEFER | L56: GuangdongFoshanREF_3TREEFER
B57: 广东 | C57: 佛山 | D57: REF_5T | E57: 冷藏 | H57: =VLOOKUP(B57,Sheet1!A:B,2,0) -> Guangdong | I57: =VLOOKUP(C57,Sheet1!C:D,2,0) -> Foshan | J57: REF_5T | K57: REEFER | L57: GuangdongFoshanREF_5TREEFER
B58: 广东 | C58: 河源 | D58: 10T | E58: 干货 | F58: 3 | G58: 4860 | H58: =VLOOKUP(B58,Sheet1!A:B,2,0) -> Guangdong | I58: =VLOOKUP(C58,Sheet1!C:D,2,0) -> Heyuan | J58: 10T | K58: DRY | L58: GuangdongHeyuan10TDRY
B59: 广东 | C59: 河源 | D59: 26T | E59: 干货 | F59: 3 | G59: 8200 | H59: =VLOOKUP(B59,Sheet1!A:B,2,0) -> Guangdong | I59: =VLOOKUP(C59,Sheet1!C:D,2,0) -> Heyuan | J59: 26T | K59: DRY | L59: GuangdongHeyuan26TDRY
B60: 广东 | C60: 河源 | D60: 3T | E60: 干货 | F60: 3 | G60: 3120 | H60: =VLOOKUP(B60,Sheet1!A:B,2,0) -> Guangdong | I60: =VLOOKUP(C60,Sheet1!C:D,2,0) -> Heyuan | J60: 3T | K60: DRY | L60: GuangdongHeyuan3TDRY
B61: 广东 | C61: 河源 | D61: DG_5T | E61: 危险品 | H61: =VLOOKUP(B61,Sheet1!A:B,2,0) -> Guangdong | I61: =VLOOKUP(C61,Sheet1!C:D,2,0) -> Heyuan | J61: DG_5T | K61: HAZMAT | L61: GuangdongHeyuanDG_5THAZMAT
B62: 广东 | C62: 惠州 | D62: DG_10T | E62: 危险品 | H62: =VLOOKUP(B62,Sheet1!A:B,2,0) -> Guangdong | I62: =VLOOKUP(C62,Sheet1!C:D,2,0) -> Huizhou | J62: DG_10T | K62: HAZMAT | L62: GuangdongHuizhouDG_10THAZMAT
B63: 广东 | C63: 惠州 | D63: 12T | E63: 干货 | F63: 3 | G63: 5280 | H63: =VLOOKUP(B63,Sheet1!A:B,2,0) -> Guangdong | I63: =VLOOKUP(C63,Sheet1!C:D,2,0) -> Huizhou | J63: 12T | K63: DRY | L63: GuangdongHuizhou12TDRY
B64: 广东 | C64: 惠州 | D64: 15T | E64: 干货 | F64: 3 | G64: 6960 | H64: =VLOOKUP(B64,Sheet1!A:B,2,0) -> Guangdong | I64: =VLOOKUP(C64,Sheet1!C:D,2,0) -> Huizhou | J64: 15T | K64: DRY | L64: GuangdongHuizhou15TDRY
...

Sheet 零担费率
B1: 零担费率
B2: 费率由运输部（MOT）审定。所报费率不得以捆绑中标为条件。
B4: 目的地
B5: SHDR DC1（主配送中心）：上海临港新城普洛斯临港物流园洋浩路575号， 中国上海市浦东新区
B6: TDSC 配送中心：上海市奉贤区航塘公路3088号C栋3楼迪士尼商店仓库，开瑞益上海配送中心C3，上海市奉贤区航塘公路3088号
F8: SHDR DC1/TDSC DC
B9: 币种：人民币 | C9: 不含增值税 | F9: 费率（人民币）
B10: 出发省份 | C10: 出发城市 | D10: 2027年预测货量合计（立方米） | E10: 历史发运次数 | F10: 运输天数（不含提货日） | G10: 最低收费（人民币）不含增值税 | H10: 费率（人民币/公斤）不含增值税
B11: 安徽 | C11: 巢湖 | D11: 227.23304 | E11: 11 | F11: 2 | G11: 280 | H11: 0.3976
B12: 安徽 | C12: 滁州 | D12: 21.71286 | E12: 2 | F12: 3 | G12: 280 | H12: 0.4108
B13: 安徽 | C13: 天长 | D13: 154.52583 | E13: 20 | F13: 2 | G13: 280 | H13: 0.4639
B14: 安徽 | C14: 宣城 | D14: 7.2174 | E14: 2 | F14: 2 | G14: 280 | H14: 0.3976
B15: 福建 | C15: 泉州 | D15: 91.57886 | E15: 10 | F15: 3 | G15: 300 | H15: 0.5964
B16: 福建 | C16: 石狮 | D16: 86.01258 | E16: 65 | F16: 3 | G16: 300 | H16: 0.5964
B17: 福建 | C17: 厦门 | D17: 19.488026 | E17: 8 | F17: 3 | G17: 300 | H17: 0.5633
B18: 福建 | C18: 漳州 | D18: 105.74955 | E18: 22 | F18: 3 | G18: 300 | H18: 0.5633
B19: 广东 | C19: 潮州 | D19: 203.64365 | E19: 16 | F19: 3 | G19: 350 | H19: 0.5964
B20: 广东 | C20: 东莞 | D20: 3200.3876 | E20: 450 | F20: 3 | G20: 350 | H20: 0.5964
B21: 广东 | C21: 佛山 | D21: 13.998618 | E21: 2 | F21: 3 | G21: 350 | H21: 0.5964
B22: 广东 | C22: 广州 | D22: 11.6629 | E22: 1 | F22: 3 | G22: 350 | H22: 0.5964
... B60: 浙江 | C60: 台州 | D60: 0.6084 | E60: 1 | F60: 2 | G60: 280 | H60: 0.3645
B61: 北海 | C61: 广西 | F61: 5 | G61: 350 | H61: 0.7289
B62: 温州 | C62: 浙江 | F62: 2 | G62: 280 | H62: 0.3645

Sheet Sheet1
A2: 起始省份 | B2: 起始省份 | C2: 起始城市 | D2: 起始城市
A3: 安徽 | B3: Anhui | C3: 安康 | D3: Ankang
A4: 福建 | B4: Fujian | C4: 北海 | D4: Beihai
A5: 广东 | B5: Guangdong | C5: 常州 | D5: Changzhou
A6: 广西 | B6: Guangxi | C6: 巢湖 | D6: Chaohu
A7: 河北 | B7: Hebei | C7: 郴州 | D7: Chenzhou
A8: 湖南 | B8: Hunan | C8: 东莞 | D8: Dongguan
A9: 江苏 | B9: Jiangsu | C9: 佛山 | D9: Foshan
A10: 江西 | B10: Jiangxi | C10: 赣州 | D10: Ganzhou
A11: 山东 | B11: Shandong | C11: 河池 | D11: Hechi
A12: 山西 | B12: Shanxi | C12: 河间 | D12: Hejian
A13: 上海 | B13: Shanghai | C13: 河源 | D13: Heyuan
A14: 浙江 | B14: Zhejiang | C14: 湖州 | D14: Huzhou
C15: 惠州 | D15: Huizhou
C16: 江门 | D16: Jiangmen
C17: 连云港 | D17: Lianyungang
C18: 南昌 | D18: Nanchang
C19: 宁波 | D19: Ningbo
C20: 平湖 | D20: Pinghu
C21: 浦北 | D21: Pubei
C22: 钦州 | D22: Qinzhou
C23: 青岛 | D23: Qingdao
C24: 泉州 | D24: Quanzhou
C25: 汕头 | D25: Shantou
C26: 上海 | D26: Shanghai
... C41: 资兴 | D41: Zixing
