Workbook
Name airvendorbuyer: #REF!
Name qryFiscalFeu_Main: #REF!

Sheet TL Capacities
B2: Loading Capacity
B3: Dry & Hazmat truck
B4: Equipment Type | C4: Physical loading capacity
B5: 3T | C5: 12
B6: 5T | C6: 23
B7: 8T | C7: 32
B8: 10T | C8: 40
B9: 12T | C9: 45
B10: 15T | C10: 55
B11: 25T | C11: 90
B12: 26T | C12: 110
B13: 30T | C13: 145
B14: 20' Container | C14: 28
B15: 40'Container | C15: 58
B16: 40'HQ Container | C16: 68

Sheet FTL
B1: FULL TRUCK RATES | Z1: P&L | AC1: Type | AD1: 車次 | AE1: AR | AF1: AP | AG1: 毛利(年,RMB) | AH1: 毛利(年,%)
B2: Rates to be awarded by MOT. Rates submitted must not be contingent upon bundled award. | AC2: FTL | AD2: =SUM(AD11:AD415) -> 1157 | AE2: =SUM(AE11:AE415) -> 5967953 | AF2: =SUM(AF11:AF415) -> 5892350 | AG2: =AE2-AF2 -> 75603 | AH2: =AG2/AF2 -> 0.012830704
AC3: LTL | AE3: =SUM(LTL!AA11:AA62) -> 2081093.3 | AF3: =SUM(LTL!AB11:AB62) -> 1891053.9 | AG3: =AE3-AF3 -> 190039.34 | AH3: =AG3/AF3 -> 0.10049388
B4: Destinations | AC4: 國內海運 | AE4: ='Domestic Ocean'!P11 -> 113136 | AF4: ='Domestic Ocean'!Q11 -> 94280 | AG4: =AE4-AF4 -> 18856 | AH4: =AG4/AF4 -> 0.2
B5: SHDR DC1(Main DC):上海临港新城普洛斯临港物流园洋浩路575号 No.575 Yanghao Road, Pudong New District, Shanghai, China | AC5: 客服成本 | AE5: 0 | AF5: =15000*12*0.5 -> 90000 | AG5: =AE5-AF5 -> -90000
B6: TDSC DC:上海市奉贤区航塘公路3088号C栋3楼DISNEY STORE WAREHOUSE,KERRYEAS SHANGHAI DISTRIBUTION CENTER C3,3088 HANGTANG HIGHWAY,FENGXIAN DISTRICT, SHANGHAI | AC6: 調度成本 | AE6: 0 | AF6: =10000*12*1 -> 120000 | AG6: =AE6-AF6 -> -120000
B7: Currency :RMB | C7: Exclude VAT | AC7: 系统对接成本 | AE7: 0 | AF7: 60000 | AG7: =AE7-AF7 -> -60000
AC8: 保险成本 | AE8: 0 | AF8: 0 | AG8: =AE8-AF8 -> 0
H9: SHDR DC1/TDSC DC | I9: AP | L9: AP | Q9: AP | AC9: 綜合評估 | AE9: =SUM(AE2:AE8) -> 8162182.3 | AF9: =SUM(AF2:AF8) -> 8147683.9 | AG9: =SUM(AG2:AG8) -> 14498.34 | AH9: =AG9/AF9 -> 0.0017794431
B10: From Province | C10: From City | D10: 省 | E10: 市 | F10: Lorry Size | G10: Temperature | H10: SHDR DC1/TDSC DC | I10: Rate (RMB) Excluding VAT | J10: REMARK | K10: 产品归属 | L10: 蔡焱南8/27 12:00报价 | M10: 运输天数 (不含提货日) | N10: 蔡焱南8/27报价 | O10: 蔡焱南8/27 12:00报价 | P10: 8/27目標價 | Q10: 王峰8/26报价 | R10: 运输天数 (不含提货日) | S10: 價格 | T10: 比對結果 | U10: I-L欄 | V10: (I-L)/I | W10: AR | Y10: Accessorial Description | Z10: Accessorial Charge per Occurrence (RMB) | AB10: 利潤 | AC10: AR (RMB） | AD10: 預計貨量 | AE10: 預計營收 | AF10: 預計成本
A11: =B11&C11&F11&G11 -> AnhuiChaohu10TDRY | B11: Anhui | C11: Chaohu | D11: 安徽 | E11: 巢湖 | F11: 10T | G11: DRY | H11: 1 | I11: 2750 | K11: 华东-孙理想 | L11: =VLOOKUP(A11,'供應商0827 - 1200更新線路報價'!A:H,8,0) -> 2430 | M11: 1 | N11: 2200 | O11: =IFERROR(VLOOKUP(B11&C11&F11&G11,'供應商0827 - 1200更新線路報價'!A:H,8,0),"") -> 2430 | Q11: 2430 | R11: 1 | S11: =MIN(I11,L11,Q11) -> 2430 | T11: =IF(S11=I11,"總部產品",IF(S11=L11,"蔡焱南","王峰")) -> 蔡焱南 | U11: =I11-L11 -> 320 | V11: =U11/I11 -> 0.11636364 | W11: =I11 -> 2750 | Y11: Stop off charge (¥) | AB11: =AC11/I11-1 -> 0 | AC11: =W11 -> 2750 | AD11: =IFERROR(VLOOKUP(B11&C11&F11,'FTL volume (customer provided)'!B:E,4,0),"") | AE11: =IFERROR(AC11*AD11,"") | AF11: =IFERROR(AD11*I11,"")
A12: =B12&C12&F12&G12 -> AnhuiChaohu12TDRY | B12: Anhui | C12: Chaohu | D12: 安徽 | E12: 巢湖 | F12: 12T | G12: DRY | H12: 1 | I12: 2850 | K12: 华东-孙理想 | L12: =VLOOKUP(A12,'供應商0827 - 1200更新線路報價'!A:H,8,0) -> 2310 | M12: 1 | N12: 2310 | O12: =IFERROR(VLOOKUP(B12&C12&F12&G12,'供應商0827 - 1200更新線路報價'!A:H,8,0),"") -> 2310 | Q12: 2760 | R12: 1 | S12: =MIN(I12,L12,Q12) -> 2310 | T12: =IF(S12=I12,"總部產品",IF(S12=L12,"蔡焱南","王峰")) -> 蔡焱南 | U12: =I12-L12 -> 540 | V12: =U12/I12 -> 0.18947368 | W12: =I12 -> 2850 | Y12: Tallyman Fee (¥)* | AB12: =AC12/I12-1 -> 0 | AC12: =W12 -> 2850 | AD12: =IFERROR(VLOOKUP(B12&C12&F12,'FTL volume (customer provided)'!B:E,4,0),"") | AE12: =IFERROR(AC12*AD12,"") | AF12: =IFERROR(AD12*I12,"")
A13: =B13&C13&F13&G13 -> AnhuiChaohu15TDRY | B13: Anhui | C13: Chaohu | D13: 安徽 | E13: 巢湖 | F13: 15T | G13: DRY | H13: 1 | I13: 3000 | K13: 华东-孙理想 | L13: =VLOOKUP(A13,'供應商0827 - 1200更新線路報價'!A:H,8,0) -> 2595 | M13: 1 | N13: 2593.5 | O13: =IFERROR(VLOOKUP(B13&C13&F13&G13,'供應商0827 - 1200更新線路報價'!A:H,8,0),"") -> 2595 | Q13: 2980 | R13: 1 | S13: =MIN(I13,L13,Q13) -> 2595 | T13: =IF(S13=I13,"總部產品",IF(S13=L13,"蔡焱南","王峰")) -> 蔡焱南 | U13: =I13-L13 -> 405 | V13: =U13/I13 -> 0.135 | W13: =I13 -> 3000 | Y13: HAZMAT (¥) | AB13: =AC13/I13-1 -> 0 | AC13: =W13 -> 3000 | AD13: =IFERROR(VLOOKUP(B13&C13&F13,'FTL volume (customer provided)'!B:E,4,0),"") | AE13: =IFERROR(AC13*AD13,"") | AF13: =IFERROR(AD13*I13,"")
A14: =B14&C14&F14&G14 -> AnhuiChaohu26TDRY | B14: Anhui | C14: Chaohu | D14: 安徽 | E14: 巢湖 | F14: 26T | G14: DRY | H14: 1 | I14: 4250 | K14: 华东-孙理想 | L14: =VLOOKUP(A14,'供應商0827 - 1200更新線路報價'!A:H,8,0) -> 3975 | M14: 1 | N14: 3400 | O14: =IFERROR(VLOOKUP(B14&C14&F14&G14,'供應商0827 - 1200更新線路報價'!A:H,8,0),"") -> 3975 | Q14: 3975 | R14: 1 | S14: =MIN(I14,L14,Q14) -> 3975 | T14: =IF(S14=I14,"總部產品",IF(S14=L14,"蔡焱南","王峰")) -> 蔡焱南 | U14: =I14-L14 -> 275 | V14: =U14/I14 -> 0.064705882 | W14: =ROUNDUP(I14*1.02,0) -> 4335 | Y14: Empty Fee (truck ordered, not used) (¥) | AB14: =AC14/I14-1 -> 0.02 | AC14: =W14 -> 4335 | AD14: =IFERROR(VLOOKUP(B14&C14&F14,'FTL volume (customer provided)'!B:E,4,0),"") -> 328 | AE14: =IFERROR(AC14*AD14,"") -> 1421880 | AF14: =IFERROR(AD14*I14,"") -> 1394000
A15: =B15&C15&F15&G15 -> AnhuiChaohu3TDRY | B15: Anhui | C15: Chaohu | D15: 安徽 | E15: 巢湖 | F15: 3T | G15: DRY | H15: 1 | I15: 1450 | K15: 华东-孙理想 | L15: =VLOOKUP(A15,'供應商0827 - 1200更新線路報價'!A:H,8,0) -> 1220 | M15: 1 | N15: 1160 | O15: =IFERROR(VLOOKUP(B15&C15&F15&G15,'供應商0827 - 1200更新線路報價'!A:H,8,0),"") -> 1220 | Q15: 1220 | R15: 1 | S15: =MIN(I15,L15,Q15) -> 1220 | T15: =IF(S15=I15,"總部產品",IF(S15=L15,"蔡焱南","王峰")) -> 蔡焱南 | U15: =I15-L15 -> 230 | V15: =U15/I15 -> 0.15862069 | W15: =I15 -> 1450 | AB15: =AC15/I15-1 -> 0 | AC15: =W15 -> 1450 | AD15: =IFERROR(VLOOKUP(B15&C15&F15,'FTL volume (customer provided)'!B:E,4,0),"") | AE15: =IFERROR(AC15*AD15,"") | AF15: =IFERROR(AD15*I15,"")
A16: =B16&C16&F16&G16 -> AnhuiChaohu5TDRY | B16: Anhui | C16: Chaohu | D16: 安徽 | E16: 巢湖 | F16: 5T | G16: DRY | H16: 1 | I16: 2450 | K16: 华东-孙理想 | L16: =VLOOKUP(A16,'供應商0827 - 1200更新線路報價'!A:H,8,0) -> 2100 | M16: 1 | N16: 1960 | O16: =IFERROR(VLOOKUP(B16&C16&F16&G16,'供應商0827 - 1200更新線路報價'!A:H,8,0),"") -> 2100 | Q16: 2100 | R16: 1 | S16: =MIN(I16,L16,Q16) -> 2100 | T16: =IF(S16=I16,"總部產品",IF(S16=L16,"蔡焱南","王峰")) -> 蔡焱南 | U16: =I16-L16 -> 350 | V16: =U16/I16 -> 0.14285714 | W16: =I16 -> 2450 | AB16: =AC16/I16-1 -> 0 | AC16: =W16 -> 2450 | AD16: =IFERROR(VLOOKUP(B16&C16&F16,'FTL volume (customer provided)'!B:E,4,0),"") | AE16: =IFERROR(AC16*AD16,"") | AF16: =IFERROR(AD16*I16,"")
A17: =B17&C17&F17&G17 -> AnhuiChaohu8TDRY | B17: Anhui | C17: Chaohu | D17: 安徽 | E17: 巢湖 | F17: 8T | G17: DRY | H17: 1 | I17: 2550 | K17: 华东-孙理想 | L17: =VLOOKUP(A17,'供應商0827 - 1200更新線路報價'!A:H,8,0) -> 2205 | M17: 1 | N17: 2040 | O17: =IFERROR(VLOOKUP(B17&C17&F17&G17,'供應商0827 - 1200更新線路報價'!A:H,8,0),"") -> 2205 | Q17: 2205 | R17: 1 | S17: =MIN(I17,L17,Q17) -> 2205 | T17: =IF(S17=I17,"總部產品",IF(S17=L17,"蔡焱南","王峰")) -> 蔡焱南 | U17: =I17-L17 -> 345 | V17: =U17/I17 -> 0.13529412 | W17: =I17 -> 2550 | AB17: =AC17/I17-1 -> 0 | AC17: =W17 -> 2550 | AD17: =IFERROR(VLOOKUP(B17&C17&F17,'FTL volume (customer provided)'!B:E,4,0),"") | AE17: =IFERROR(AC17*AD17,"") | AF17: =IFERROR(AD17*I17,"")
A18: =B18&C18&F18&G18 -> AnhuiChaohu40'HQDRY - SOC | B18: Anhui | C18: Chaohu | D18: 安徽 | E18: 巢湖 | F18: 40'HQ | G18: DRY - SOC | H18: 1 | I18: 3750 | K18: 华东-孙理想 | L18: =VLOOKUP(A18,'供應商0827 - 1200更新線路報價'!A:H,8,0) -> 3860 | M18: 1 | N18: 3750 | O18: =IFERROR(VLOOKUP(B18&C18&F18&G18,'供應商0827 - 1200更新線路報價'!A:H,8,0),"") -> 3860 | Q18: 3860 | R18: 1 | S18: =MIN(I18,L18,Q18) -> 3750 | T18: =IF(L18=S18,"蔡焱南",IF(S18=I18,"總部產品",IF(S18=L18,"蔡焱南","王峰"))) -> 總部產品 | U18: =I18-L18 -> -110 | V18: =U18/I18 -> -0.029333333 | W18: =ROUNDUP(I18*1.02,0) -> 3825 | AB18: =AC18/I18-1 -> 0.02 | AC18: =W18 -> 3825 | AD18: =IFERROR(VLOOKUP(B18&C18&F18,'FTL volume (customer provided)'!B:E,4,0),"") -> 20 | AE18: =IFERROR(AC18*AD18,"") -> 76500 | AF18: =IFERROR(AD18*I18,"") -> 75000
A19: =B19&C19&F19&G19 -> AnhuiTianchang10TDRY | B19: Anhui | C19: Tianchang | D19: 安徽 | E19: 天长 | F19: 10T | G19: DRY | H19: 1 | I19: 2450 | K19: 华东-孙理想 | L19: =VLOOKUP(A19,'供應商0827 - 1200更新線路報價'!A:H,8,0) -> 2205 | M19: 1 | N19: 2047.5 | O19: =IFERROR(VLOOKUP(B19&C19&F19&G19,'供應商0827 - 1200更新線路報價'!A:H,8,0),"") -> 2205 | Q19: 2205 | R19: 1 | S19: =MIN(I19,L19,Q19) -> 2205 | T19: =IF(S19=I19,"總部產品",IF(S19=L19,"蔡焱南","王峰")) -> 蔡焱南 | U19: =I19-L19 -> 245 | V19: =U19/I19 -> 0.1 | W19: =I19 -> 2450 | AB19: =AC19/I19-1 -> 0 | AC19: =W19 -> 2450 | AD19: =IFERROR(VLOOKUP(B19&C19&F19,'FTL volume (customer provided)'!B:E,4,0),"") | AE19: =IFERROR(AC19*AD19,"") | AF19: =IFERROR(AD19*I19,"")
A20: =B20&C20&F20&G20 -> AnhuiTianchang12TDRY | B20: Anhui | C20: Tianchang | D20: 安徽 | E20: 天长 | F20: 12T | G20: DRY | H20: 1 | I20: 2550 | K20: 华东-孙理想 | L20: =VLOOKUP(A20,'供應商0827 - 1200更新線路報價'!A:H,8,0) -> 2540 | M20: 1 | N20: 3097.5 | O20: =IFERROR(VLOOKUP(B20&C20&F20&G20,'供應商0827 - 1200更新線路報價'!A:H,8,0),"") -> 2540 | P20: 2540 | Q20: 2540 | R20: 1 | S20: =MIN(I20,L20,Q20) -> 2540 | T20: =IF(L20=S20,"蔡焱南",IF(S20=I20,"總部產品",IF(S20=L20,"蔡焱南","王峰"))) -> 蔡焱南 | U20: =I20-L20 -> 10 | V20: =U20/I20 -> 0.0039215686 | W20: =ROUNDUP(I20*1.02,0) -> 2601 | AB20: =AC20/I20-1 -> 0.02 | AC20: =W20 -> 2601 | AD20: =IFERROR(VLOOKUP(B20&C20&F20,'FTL volume (customer provided)'!B:E,4,0),"") | AE20: =IFERROR(AC20*AD20,"") | AF20: =IFERROR(AD20*I20,"")
A21: =B21&C21&F21&G21 -> AnhuiTianchang15TDRY | B21: Anhui | C21: Tianchang | D21: 安徽 | E21: 天长 | F21: 15T | G21: DRY | H21: 1 | I21: 2650 | K21: 华东-孙理想 | L21: =VLOOKUP(A21,'供應商0827 - 1200更新線路報價'!A:H,8,0) -> 2760 | M21: 1 | N21: 2650 | O21: =IFERROR(VLOOKUP(B21&C21&F21&G21,'供應商0827 - 1200更新線路報價'!A:H,8,0),"") -> 2760 | Q21: 2760 | R21: 1 | S21: =MIN(I21,L21,Q21) -> 2650 | T21: 蔡焱南 | U21: =I21-L21 -> -110 | V21: =U21/I21 -> -0.041509434 | W21: =ROUNDUP(I21*1.02,0) -> 2703 | AB21: =AC21/I21-1 -> 0.02 | AC21: =W21 -> 2703 | AD21: =IFERROR(VLOOKUP(B21&C21&F21,'FTL volume (customer provided)'!B:E,4,0),"") -> 7 | AE21: =IFERROR(AC21*AD21,"") -> 18921 | AF21: =IFERROR(AD21*I21,"") -> 18550
A22: =B22&C22&F22&G22 -> AnhuiTianchang25TDRY | B22: Anhui | C22: Tianchang | D22: 安徽 | E22: 天长 | F22: 25T | G22: DRY | H22: 1 | I22: 3150 | K22: 华东-孙理想 | L22: =VLOOKUP(A22,'供應商0827 - 1200更新線路報價'!A:H,8,0) -> 3640 | M22: 1 | N22: 3150 | O22: =IFERROR(VLOOKUP(B22&C22&F22&G22,'供應商0827 - 1200更新線路報價'!A:H,8,0),"") -> 3640 | Q22: 3640 | R22: 1 | S22: =MIN(I22,L22,Q22) -> 3150 | T22: 蔡焱南 | U22: =I22-L22 -> -490 | V22: =U22/I22 -> -0.15555556 | W22: =I22*1.06 -> 3339 | AB22: =AC22/I22-1 -> 0.06 | AC22: =W22 -> 3339 | AD22: =IFERROR(VLOOKUP(B22&C22&F22,'FTL volume (customer provided)'!B:E,4,0),"") -> 127 | AE22: =IFERROR(AC22*AD22,"") -> 424053 | AF22: =IFERROR(AD22*I22,"") -> 400050
A23: =B23&C23&F23&G23 -> AnhuiTianchang26TDRY | B23: Anhui | C23: Tianchang | D23: 安徽 | E23: 天长 | F23: 26T | G23: DRY | H23: 1 | I23: 3450 | K23: 华东-孙理想 | L23: =VLOOKUP(A23,'供應商0827 - 1200更新線路報價'!A:H,8,0) -> 3640 | M23: 1 | N23: 3450 | O23: =IFERROR(VLOOKUP(B23&C23&F23&G23,'供應商0827 - 1200更新線路報價'!A:H,8,0),"") -> 3640 | Q23: 3640 | R23: 1 | S23: =MIN(I23,L23,Q23) -> 3450 | T23: 蔡焱南 | U23: =I23-L23 -> -190 | V23: =U23/I23 -> -0.055072464 | W23: =ROUNDUP(I23*1.02,0) -> 3519 | AB23: =AC23/I23-1 -> 0.02 | AC23: =W23 -> 3519 | AD23: =IFERROR(VLOOKUP(B23&C23&F23,'FTL volume (customer provided)'!B:E,4,0),"") | AE23: =IFERROR(AC23*AD23,"") | AF23: =IFERROR(AD23*I23,"")
A24: =B24&C24&F24&G24 -> AnhuiTianchang3TDRY | B24: Anhui | C24: Tianchang | D24: 安徽 | E24: 天长 | F24: 3T | G24: DRY | H24: 1 | I24: 1400 | K24: 华东-孙理想 | L24: =VLOOKUP(A24,'供應商0827 - 1200更新線路報價'!A:H,8,0) -> 1195 | M24: 1 | N24: 1120 | O24: =IFERROR(VLOOKUP(B24&C24&F24&G24,'供應商0827 - 1200更新線路報價'!A:H,8,0),"") -> 1195 | Q24: 1195 | R24: 1 | S24: =MIN(I24,L24,Q24) -> 1195 | T24: =IF(S24=I24,"總部產品",IF(S24=L24,"蔡焱南","王峰")) -> 蔡焱南 | U24: =I24-L24 -> 205 | V24: =U24/I24 -> 0.14642857 | W24: =I24 -> 1400 | AB24: =AC24/I24-1 -> 0 | AC24: =W24 -> 1400 | AD24: =IFERROR(VLOOKUP(B24&C24&F24,'FTL volume (customer provided)'!B:E,4,0),"") | AE24: =IFERROR(AC24*AD24,"") | AF24: =IFERROR(AD24*I24,"")
A25: =B25&C25&F25&G25 -> AnhuiTianchang5TDRY | B25: Anhui | C25: Tianchang | D25: 安徽 | E25: 天长 | F25: 5T | G25: DRY | H25: 1 | I25: 2250 | K25: 华东-孙理想 | L25: =VLOOKUP(A25,'供應商0827 - 1200更新線路報價'!A:H,8,0) -> 1990 | M25: 1 | N25: 1800 | O25: =IFERROR(VLOOKUP(B25&C25&F25&G25,'供應商0827 - 1200更新線路報價'!A:H,8,0),"") -> 1990 | Q25: 1990 | R25: 1 | S25: =MIN(I25,L25,Q25) -> 1990 | T25: =IF(S25=I25,"總部產品",IF(S25=L25,"蔡焱南","王峰")) -> 蔡焱南 | U25: =I25-L25 -> 260 | V25: =U25/I25 -> 0.11555556 | W25: =I25 -> 2250 | AB25: =AC25/I25-1 -> 0 | AC25: =W25 -> 2250 | AD25: =IFERROR(VLOOKUP(B25&C25&F25,'FTL volume (customer provided)'!B:E,4,0),"") | AE25: =IFERROR(AC25*AD25,"") | AF25: =IFERROR(AD25*I25,"")
A26: =B26&C26&F26&G26 -> AnhuiTianchang8TDRY | B26: Anhui | C26: Tianchang | D26: 安徽 | E26: 天长 | F26: 8T | G26: DRY | H26: 1 | I26: 2350 | K26: 华东-孙理想 | L26: =VLOOKUP(A26,'供應商0827 - 1200更新線路報價'!A:H,8,0) -> 1990 | M26: 1 | N26: 1880 | O26: =IFERROR(VLOOKUP(B26&C26&F26&G26,'供應商0827 - 1200更新線路報價'!A:H,8,0),"") -> 1990 | Q26: 1990 | R26: 1 | S26: =MIN(I26,L26,Q26) -> 1990 | T26: =IF(S26=I26,"總部產品",IF(S26=L26,"蔡焱南","王峰")) -> 蔡焱南 | U26: =I26-L26 -> 360 | V26: =U26/I26 -> 0.15319149 | W26: =I26 -> 2350 | AB26: =AC26/I26-1 -> 0 | AC26: =W26 -> 2350 | AD26: =IFERROR(VLOOKUP(B26&C26&F26,'FTL volume (customer provided)'!B:E,4,0),"") | AE26: =IFERROR(AC26*AD26,"") | AF26: =IFERROR(AD26*I26,"")
A27: =B27&C27&F27&G27 -> AnhuiTianchang40'HQDRY - SOC | B27: Anhui | C27: Tianchang | D27: 安徽 | E27: 天长 | F27: 40'HQ | G27: DRY - SOC | H27: 1 | I27: 3750 | K27: 华东-孙理想 | L27: =VLOOKUP(A27,'供應商0827 - 1200更新線路報價'!A:H,8,0) -> 3640 | M27: 1 | N27: 3360 | O27: =IFERROR(VLOOKUP(B27&C27&F27&G27,'供應商0827 - 1200更新線路報價'!A:H,8,0),"") -> 3640 | Q27: 3640 | R27: 1 | S27: =MIN(I27,L27,Q27) -> 3640 | T27: =IF(S27=I27,"總部產品",IF(S27=L27,"蔡焱南","王峰")) -> 蔡焱南 | U27: =I27-L27 -> 110 | V27: =U27/I27 -> 0.029333333 | W27: =ROUNDUP(I27*1.02,0) -> 3825 | AB27: =AC27/I27-1 -> 0.02 | AC27: =W27 -> 3825 | AD27: =IFERROR(VLOOKUP(B27&C27&F27,'FTL volume (customer provided)'!B:E,4,0),"") | AE27: =IFERROR(AC27*AD27,"") | AF27: =IFERROR(AD27*I27,"")
A28: =B28&C28&F28&G28 -> AnhuiXuancheng26TDRY | B28: Anhui | C28: Xuancheng | D28: 安徽 | E28: 宣城 | F28: 26T | G28: DRY | H28: 1 | I28: 3050 | K28: 华东-孙理想 | L28: =VLOOKUP(A28,'供應商0827 - 1200更新線路報價'!A:H,8,0) -> 3200 | M28: 1 | N28: 3050 | O28: =IFERROR(VLOOKUP(B28&C28&F28&G28,'供應商0827 - 1200更新線路報價'!A:H,8,0),"") -> 3200 | Q28: 3200 | R28: 1 | S28: =MIN(I28,L28,Q28) -> 3050 | T28: 蔡焱南 | U28: =I28-L28 -> -150 | V28: =U28/I28 -> -0.049180328 | W28: =ROUNDUP(I28*1.02,0) -> 3111 | AB28: =AC28/I28-1 -> 0.02 | AC28: =W28 -> 3111 | AD28: =IFERROR(VLOOKUP(B28&C28&F28,'FTL volume (customer provided)'!B:E,4,0),"") | AE28: =IFERROR(AC28*AD28,"") | AF28: =IFERROR(AD28*I28,"")
A29: =B29&C29&F29&G29 -> AnhuiXuancheng3TDRY | B29: Anhui | C29: Xuancheng | D29: 安徽 | E29: 宣城 | F29: 3T | G29: DRY | H29: 1 | I29: 1150 | K29: 华东-孙理想 | L29: =VLOOKUP(A29,'供應商0827 - 1200更新線路報價'!A:H,8,0) -> 1105 | M29: 1 | N29: 920 | O29: =IFERROR(VLOOKUP(B29&C29&F29&G29,'供應商0827 - 1200更新線路報價'!A:H,8,0),"") -> 1105 | Q29: 1105 | R29: 1 | S29: =MIN(I29,L29,Q29) -> 1105 | T29: =IF(S29=I29,"總部產品",IF(S29=L29,"蔡焱南","王峰")) -> 蔡焱南 | U29: =I29-L29 -> 45 | V29: =U29/I29 -> 0.039130435 | W29: =ROUNDUP(I29*1.02,0) -> 1173 | AB29: =AC29/I29-1 -> 0.02 | AC29: =W29 -> 1173 | AD29: =IFERROR(VLOOKUP(B29&C29&F29,'FTL volume (customer provided)'!B:E,4,0),"") | AE29: =IFERROR(AC29*AD29,"") | AF29: =IFERROR(AD29*I29,"")
A30: =B30&C30&F30&G30 -> AnhuiXuancheng5TDRY | B30: Anhui | C30: Xuancheng | D30: 安徽 | E30: 宣城 | F30: 5T | G30: DRY | H30: 1 | I30: 1850 | K30: 华东-孙理想 | L30: =VLOOKUP(A30,'供應商0827 - 1200更新線路報價'!A:H,8,0) -> 1655 | M30: 1 | N30: 1480 | O30: =IFERROR(VLOOKUP(B30&C30&F30&G30,'供應商0827 - 1200更新線路報價'!A:H,8,0),"") -> 1655 | Q30: 1655 | R30: 1 | S30: =MIN(I30,L30,Q30) -> 1655 | T30: =IF(S30=I30,"總部產品",IF(S30=L30,"蔡焱南","王峰")) -> 蔡焱南 | U30: =I30-L30 -> 195 | V30: =U30/I30 -> 0.10540541 | W30: =I30 -> 1850 | AB30: =AC30/I30-1 -> 0 | AC30: =W30 -> 1850 | AD30: =IFERROR(VLOOKUP(B30&C30&F30,'FTL volume (customer provided)'!B:E,4,0),"") | AE30: =IFERROR(AC30*AD30,"") | AF30: =IFERROR(AD30*I30,"")
A31: =B31&C31&F31&G31 -> AnhuiXuancheng8TDRY | B31: Anhui | C31: Xuancheng | D31: 安徽 | E31: 宣城 | F31: 8T | G31: DRY | H31: 1 | I31: 1950 | K31: 华东-孙理想 | L31: =VLOOKUP(A31,'供應商0827 - 1200更新線路報價'!A:H,8,0) -> 1655 | M31: 1 | N31: 1560 | O31: =IFERROR(VLOOKUP(B31&C31&F31&G31,'供應商0827 - 1200更新線路報價'!A:H,8,0),"") -> 1655 | Q31: 1655 | R31: 1 | S31: =MIN(I31,L31,Q31) -> 1655 | T31: =IF(S31=I31,"總部產品",IF(S31=L31,"蔡焱南","王峰")) -> 蔡焱南 | U31: =I31-L31 -> 295 | V31: =U31/I31 -> 0.15128205 | W31: =I31 -> 1950 | AB31: =AC31/I31-1 -> 0 | AC31: =W31 -> 1950 | AD31: =IFERROR(VLOOKUP(B31&C31&F31,'FTL volume (customer provided)'!B:E,4,0),"") | AE31: =IFERROR(AC31*AD31,"") | AF31: =IFERROR(AD31*I31,"")
A32: =B32&C32&F32&G32 -> FujianQuanzhou10TDRY | B32: Fujian | C32: Quanzhou | D32: 福建 | E32: 泉州 | F32: 10T | G32: DRY | I32: 4500 | K32: 华南 - 许建生 | L32: =VLOOKUP(A32,'供應商0827 - 1200更新線路報價'!A:H,8,0) -> 3535 | M32: 2 | N32: 3375 | O32: =IFERROR(VLOOKUP(B32&C32&F32&G32,'供應商0827 - 1200更新線路報價'!A:H,8,0),"") -> 3535 | Q32: 3535 | R32: 2 | S32: =MIN(I32,L32,Q32) -> 3535 | T32: =IF(S32=I32,"總部產品",IF(S32=L32,"蔡焱南","王峰")) -> 蔡焱南 | U32: =I32-L32 -> 965 | V32: =U32/I32 -> 0.21444444 | W32: =I32 -> 4500 | AB32: =AC32/I32-1 -> 0 | AC32: =W32 -> 4500 | AD32: =IFERROR(VLOOKUP(B32&C32&F32,'FTL volume (customer provided)'!B:E,4,0),"") | AE32: =IFERROR(AC32*AD32,"") | AF32: =IFERROR(AD32*I32,"")
A33: =B33&C33&F33&G33 -> FujianQuanzhou15TDRY | B33: Fujian | C33: Quanzhou | D33: 福建 | E33: 泉州 | F33: 15T | G33: DRY | I33: 4700 | K33: 华南 - 许建生 | L33: =VLOOKUP(A33,'供應商0827 - 1200更新線路報價'!A:H,8,0) -> 3860 | M33: 2 | N33: 3760 | O33: =IFERROR(VLOOKUP(B33&C33&F33&G33,'供應商0827 - 1200更新線路報價'!A:H,8,0),"") -> 3860 | Q33: 3860 | R33: 2 | S33: =MIN(I33,L33,Q33) -> 3860 | T33: =IF(S33=I33,"總部產品",IF(S33=L33,"蔡焱南","王峰")) -> 蔡焱南 | U33: =I33-L33 -> 840 | V33: =U33/I33 -> 0.1787234 | W33: =I33 -> 4700 | AB33: =AC33/I33-1 -> 0 | AC33: =W33 -> 4700 | AD33: =IFERROR(VLOOKUP(B33&C33&F33,'FTL volume (customer provided)'!B:E,4,0),"") | AE33: =IFERROR(AC33*AD33,"") | AF33: =IFERROR(AD33*I33,"")
A34: =B34&C34&F34&G34 -> FujianQuanzhou25TDRY | B34: Fujian | C34: Quanzhou | D34: 福建 | E34: 泉州 | F34: 25T | G34: DRY | I34: 6800 | K34: 华南 - 许建生 | L34: =VLOOKUP(A34,'供應商0827 - 1200更新線路報價'!A:H,8,0) -> 5080 | M34: 2 | N34: 5080 | O34: =IFERROR(VLOOKUP(B34&C34&F34&G34,'供應商0827 - 1200更新線路報價'!A:H,8,0),"") -> 5080 | Q34: 5080 | R34: 2 | S34: =MIN(I34,L34,Q34) -> 5080 | T34: =IF(L34=S34,"蔡焱南",IF(S34=I34,"總部產品",IF(S34=L34,"蔡焱南","王峰"))) -> 蔡焱南 | U34: =I34-L34 -> 1720 | V34: =U34/I34 -> 0.25294118 | W34: =I34 -> 6800 | AB34: =AC34/I34-1 -> 0 | AC34: =W34 -> 6800 | AD34: =IFERROR(VLOOKUP(B34&C34&F34,'FTL volume (customer provided)'!B:E,4,0),"") -> 35 | AE34: =IFERROR(AC34*AD34,"") -> 238000 | AF34: =IFERROR(AD34*I34,"") -> 238000
A35: =B35&C35&F35&G35 -> FujianQuanzhou26TDRY | B35: Fujian | C35: Quanzhou | D35: 福建 | E35: 泉州 | F35: 26T | G35: DRY | I35: 6900 | K35: 华南 - 许建生 | L35: =VLOOKUP(A35,'供應商0827 - 1200更新線路報價'!A:H,8,0) -> 5295 | M35: 2 | N35: 5175 | O35: =IFERROR(VLOOKUP(B35&C35&F35&G35,'供應商0827 - 1200更新線路報價'!A:H,8,0),"") -> 5295 | Q35: 5295 | R35: 2 | S35: =MIN(I35,L35,Q35) -> 5295 | T35: =IF(S35=I35,"總部產品",IF(S35=L35,"蔡焱南","王峰")) -> 蔡焱南 | U35: =I35-L35 -> 1605 | V35: =U35/I35 -> 0.2326087 | W35: =I35 -> 6900 | AB35: =AC35/I35-1 -> 0 | AC35: =W35 -> 6900 | AD35: =IFERROR(VLOOKUP(B35&C35&F35,'FTL volume (customer provided)'!B:E,4,0),"") | AE35: =IFERROR(AC35*AD35,"") | AF35: =IFERROR(AD35*I35,"")
A36: =B36&C36&F36&G36 -> FujianQuanzhou5TDRY | B36: Fujian | C36: Quanzhou | D36: 福建 | E36: 泉州 | F36: 5T | G36: DRY | I36: 3900 | K36: 华南 - 许建生 | L36: =VLOOKUP(A36,'供應商0827 - 1200更新線路報價'!A:H,8,0) -> 2980 | M36: 2 | N36: 2925 | O36: =IFERROR(VLOOKUP(B36&C36&F36&G36,'供應商0827 - 1200更新線路報價'!A:H,8,0),"") -> 2980 | Q36: 2980 | R36: 2 | S36: =MIN(I36,L36,Q36) -> 2980 | T36: =IF(S36=I36,"總部產品",IF(S36=L36,"蔡焱南","王峰")) -> 蔡焱南 | U36: =I36-L36 -> 920 | V36: =U36/I36 -> 0.23589744 | W36: =I36 -> 3900 | AB36: =AC36/I36-1 -> 0 | AC36: =W36 -> 3900 | AD36: =IFERROR(VLOOKUP(B36&C36&F36,'FTL volume (customer provided)'!B:E,4,0),"") | AE36: =IFERROR(AC36*AD36,"") | AF36: =IFERROR(AD36*I36,"")
A37: =B37&C37&F37&G37 -> FujianQuanzhou8TDRY | B37: Fujian | C37: Quanzhou | D37: 福建 | E37: 泉州 | F37: 8T | G37: DRY | I37: 4000 | K37: 华南 - 许建生 | L37: =VLOOKUP(A37,'供應商0827 - 1200更新線路報價'!A:H,8,0) -> 3535 | M37: 2 | N37: 3200 | O37: =IFERROR(VLOOKUP(B37&C37&F37&G37,'供應商0827 - 1200更新線路報價'!A:H,8,0),"") -> 3535 | Q37: 3535 | R37: 2 | S37: =MIN(I37,L37,Q37) -> 3535 | T37: =IF(S37=I37,"總部產品",IF(S37=L37,"蔡焱南","王峰")) -> 蔡焱南 | U37: =I37-L37 -> 465 | V37: =U37/I37 -> 0.11625 | W37: =I37 -> 4000 | AB37: =AC37/I37-1 -> 0 | AC37: =W37 -> 4000 | AD37: =IFERROR(VLOOKUP(B37&C37&F37,'FTL volume (customer provided)'!B:E,4,0),"") | AE37: =IFERROR(AC37*AD37,"") | AF37: =IFERROR(AD37*I37,"")
A38: =B38&C38&F38&G38 -> FujianQuanzhou40'HQDRY - SOC | B38: Fujian | C38: Quanzhou | D38: 福建 | E38: 泉州 | F38: 40'HQ | G38: DRY - SOC | I38: 6250 | J38: DRY - SOC（自备柜） | K38: 华南 - 许建生 | L38: =VLOOKUP(A38,'供應商0827 - 1200更新線路報價'!A:H,8,0) -> 5080 | M38: 2 | N38: 5000 | O38: =IFERROR(VLOOKUP(B38&C38&F38&G38,'供應商0827 - 1200更新線路報價'!A:H,8,0),"") -> 5080 | Q38: 5080 | R38: 2 | S38: =MIN(I38,L38,Q38) -> 5080 | T38: =IF(S38=I38,"總部產品",IF(S38=L38,"蔡焱南","王峰")) -> 蔡焱南 | U38: =I38-L38 -> 1170 | V38: =U38/I38 -> 0.1872 | W38: =I38 -> 6250 | AB38: =AC38/I38-1 -> 0 | AC38: =W38 -> 6250 | AD38: =IFERROR(VLOOKUP(B38&C38&F38,'FTL volume (customer provided)'!B:E,4,0),"") -> 5 | AE38: =IFERROR(AC38*AD38,"") -> 31250 | AF38: =IFERROR(AD38*I38,"") -> 31250
A39: =B39&C39&F39&G39 -> FujianShishi3TDRY | B39: Fujian | C39: Shishi | D39: 福建 | E39: 石狮 | F39: 3T | G39: DRY | I39: 2950 | K39: 华南 - 许建生 | L39: =VLOOKUP(A39,'供應商0827 - 1200更新線路報價'!A:H,8,0) -> 2205 | M39: 2 | N39: 2205 | O39: =IFERROR(VLOOKUP(B39&C39&F39&G39,'供應商0827 - 1200更新線路報價'!A:H,8,0),"") -> 2205 | Q39: 2205 | R39: 2 | S39: =MIN(I39,L39,Q39) -> 2205 | T39: =IF(L39=S39,"蔡焱南",IF(S39=I39,"總部產品",IF(S39=L39,"蔡焱南","王峰"))) -> 蔡焱南 | U39: =I39-L39 -> 745 | V39: =U39/I39 -> 0.25254237 | W39: =I39 -> 2950 | AB39: =AC39/I39-1 -> 0 | AC39: =W39 -> 2950 | AD39: =IFERROR(VLOOKUP(B39&C39&F39,'FTL volume (customer provided)'!B:E,4,0),"") | AE39: =IFERROR(AC39*AD39,"") | AF39: =IFERROR(AD39*I39,"")
A40: =B40&C40&F40&G40 -> FujianShishi5TDRY | B40: Fujian | C40: Shishi | D40: 福建 | E40: 石狮 | F40: 5T | G40: DRY | I40: 3900 | K40: 华南 - 许建生 | L40: =VLOOKUP(A40,'供應商0827 - 1200更新線路報價'!A:H,8,0) -> 2875 | M40: 2 | N40: 2875 | O40: =IFERROR(VLOOKUP(B40&C40&F40&G40,'供應商0827 - 1200更新線路報價'!A:H,8,0),"") -> 2875 | Q40: 2875 | R40: 2 | S40: =MIN(I40,L40,Q40) -> 2875 | T40: =IF(L40=S40,"蔡焱南",IF(S40=I40,"總部產品",IF(S40=L40,"蔡焱南","王峰"))) -> 蔡焱南 | U40: =I40-L40 -> 1025 | V40: =U40/I40 -> 0.26282051 | W40: =I40 -> 3900 | AB40: =AC40/I40-1 -> 0 | AC40: =W40 -> 3900 | AD40: =IFERROR(VLOOKUP(B40&C40&F40,'FTL volume (customer provided)'!B:E,4,0),"") -> 4 | AE40: =IFERROR(AC40*AD40,"") -> 15600 | AF40: =IFERROR(AD40*I40,"") -> 15600
...

Sheet LTL
B1: LESS THAN TRUCKLOAD RATES
B2: Rates to be awarded by MOT. Rates submitted must not be contingent upon bundled award.
B4: Destinations
B5: SHDR DC1(Main DC):上海临港新城普洛斯临港物流园洋浩路575号 No.575 Yanghao Road, Pudong New District, Shanghai, China
B6: TDSC DC:上海市奉贤区航塘公路3088号C栋3楼DISNEY STORE WAREHOUSE,KERRYEAS SHANGHAI DISTRIBUTION CENTER C3,3088 HANGTANG HIGHWAY,FENGXIAN DISTRICT, SHANGHAI
F8: SHDR DC1/TDSC DC
B9: Currency :RMB | C9: Exclude VAT | F9: Rate (RMB) | J9: 蔡焱南8/27報價 | M9: 王峰AP | T9: 一輪AR | X9: AR (RMB）
B10: Origin Province | C10: Origin City | D10: Sum of 2027 Projected vol(cbm) | E10: Historical No. of Shipments | F10: Transit Days (excluding pick up day) | G10: Minimum Charge (RMB) excluding VAT | H10: Rate (RMB) per Kg excluding VAT | J10: Transit Days (excluding pick up day) | K10: Minimum Charge (RMB) excluding VAT | L10: Rate (RMB) per Kg excluding VAT | M10: Transit Days (excluding pick up day) | N10: Minimum Charge (RMB) excluding VAT | O10: Rate (RMB) per Kg excluding VAT | P10: MIN價格 | Q10: 比對結果 | R10: KG Rate | S10: 比對結果 | T10: Minimum Charge (RMB) excluding VAT | U10: Rate (RMB) per Kg excluding VAT | W10: 利潤 | X10: Minimum Charge (RMB) excluding VAT | Y10: Rate (RMB) per Kg excluding VAT | Z10: 平均每批貨量 | AA10: 預計營收 | AB10: 預計成本
A11: =B11&C11 -> AnhuiChaohu | B11: Anhui | C11: Chaohu | D11: 227.23304 | E11: 11 | F11: 2 | G11: 500 | H11: 0.35 | I11: 华东 - 孙理想 | J11: 2 | K11: 300 | L11: 0.35 | M11: 2 | N11: 400 | O11: 0.399 | P11: =MIN(G11,K11,N11) -> 300 | Q11: =IF(P11=K11,"蔡焱南",IF(P11=G11,"總部產品",IF(P11=K11,"蔡焱南","王峰"))) -> 蔡焱南 | R11: =MIN(H11,L11,O11) -> 0.35 | S11: =IF(L11=R11,"蔡焱南",IF(R11=H11,"總部產品",IF(R11=L11,"蔡焱南","王峰"))) -> 蔡焱南 | T11: =ROUNDUP(G11*1.1,0) -> 550 | U11: =ROUNDUP(H11*1.1,2) -> 0.39 | W11: 0.15 | X11: =T11 -> 550 | Y11: =U11 -> 0.39 | Z11: =ROUNDUP(D11/E11*166.67,0) -> 3443 | AA11: =MAX(X11,Z11*Y11)*E11 -> 14770.47 | AB11: =MAX(G11,Z11*H11)*E11 -> 13255.55
A12: =B12&C12 -> AnhuiChuzhou | B12: Anhui | C12: Chuzhou | D12: 21.71286 | E12: 2 | F12: 2 | G12: 500 | H12: 0.35 | I12: 华东 - 孙理想 | J12: 2 | K12: 300 | L12: 0.35 | M12: 2 | N12: 400 | O12: 0.42 | P12: =MIN(G12,K12,N12) -> 300 | Q12: =IF(P12=K12,"蔡焱南",IF(P12=G12,"總部產品",IF(P12=K12,"蔡焱南","王峰"))) -> 蔡焱南 | R12: =MIN(H12,L12,O12) -> 0.35 | S12: =IF(L12=R12,"蔡焱南",IF(R12=H12,"總部產品",IF(R12=L12,"蔡焱南","王峰"))) -> 蔡焱南 | T12: =ROUNDUP(G12*1.1,0) -> 550 | U12: =ROUNDUP(H12*1.1,2) -> 0.39 | W12: 0.15 | X12: =T12 -> 550 | Y12: =U12 -> 0.39 | Z12: =ROUNDUP(D12/E12*166.67,0) -> 1810 | AA12: =MAX(X12,Z12*Y12)*E12 -> 1411.8 | AB12: =MAX(G12,Z12*H12)*E12 -> 1267
A13: =B13&C13 -> AnhuiTianchang | B13: Anhui | C13: Tianchang | D13: 154.52583 | E13: 20 | F13: 2 | G13: 500 | H13: 0.38 | I13: 华东 - 孙理想 | J13: 2 | K13: 300 | L13: 0.38 | M13: 2 | N13: 400 | O13: 0.42 | P13: =MIN(G13,K13,N13) -> 300 | Q13: =IF(P13=K13,"蔡焱南",IF(P13=G13,"總部產品",IF(P13=K13,"蔡焱南","王峰"))) -> 蔡焱南 | R13: =MIN(H13,L13,O13) -> 0.38 | S13: =IF(L13=R13,"蔡焱南",IF(R13=H13,"總部產品",IF(R13=L13,"蔡焱南","王峰"))) -> 蔡焱南 | T13: =ROUNDUP(G13*1.1,0) -> 550 | U13: =ROUNDUP(H13*1.1,2) -> 0.42 | W13: 0.15 | X13: =T13 -> 550 | Y13: =U13 -> 0.42 | Z13: =ROUNDUP(D13/E13*166.67,0) -> 1288 | AA13: =MAX(X13,Z13*Y13)*E13 -> 11000 | AB13: =MAX(G13,Z13*H13)*E13 -> 10000
A14: =B14&C14 -> AnhuiXuancheng | B14: Anhui | C14: Xuancheng | D14: 7.2174 | E14: 2 | F14: 2 | G14: 500 | H14: 0.35 | I14: 华东 - 孙理想 | J14: 2 | K14: 300 | L14: 0.35 | M14: 2 | N14: 400 | O14: 0.42 | P14: =MIN(G14,K14,N14) -> 300 | Q14: =IF(P14=K14,"蔡焱南",IF(P14=G14,"總部產品",IF(P14=K14,"蔡焱南","王峰"))) -> 蔡焱南 | R14: =MIN(H14,L14,O14) -> 0.35 | S14: =IF(L14=R14,"蔡焱南",IF(R14=H14,"總部產品",IF(R14=L14,"蔡焱南","王峰"))) -> 蔡焱南 | T14: =ROUNDUP(G14*1.1,0) -> 550 | U14: =ROUNDUP(H14*1.1,2) -> 0.39 | W14: 0.15 | X14: =T14 -> 550 | Y14: =U14 -> 0.39 | Z14: =ROUNDUP(D14/E14*166.67,0) -> 602 | AA14: =MAX(X14,Z14*Y14)*E14 -> 1100 | AB14: =MAX(G14,Z14*H14)*E14 -> 1000
A15: =B15&C15 -> FujianQuanzhou | B15: Fujian | C15: Quanzhou | D15: 91.57886 | E15: 10 | F15: 2 | G15: 450 | H15: 1.1 | I15: 华南 - 许建生 | J15: 3 | K15: 400 | L15: 0.4725 | M15: 3 | N15: 400 | O15: 0.4725 | P15: =MIN(G15,K15,N15) -> 400 | Q15: =IF(P15=K15,"蔡焱南",IF(P15=G15,"總部產品",IF(P15=K15,"蔡焱南","王峰"))) -> 蔡焱南 | R15: =MIN(H15,L15,O15) -> 0.4725 | S15: =IF(L15=R15,"蔡焱南",IF(R15=H15,"總部產品",IF(R15=L15,"蔡焱南","王峰"))) -> 蔡焱南 | T15: =ROUNDUP(G15*1.1,0) -> 495 | U15: =ROUNDUP(H15*1.1,2) -> 1.21 | W15: 0.15 | X15: =T15 -> 495 | Y15: =U15 -> 1.21 | Z15: =ROUNDUP(D15/E15*166.67,0) -> 1527 | AA15: =MAX(X15,Z15*Y15)*E15 -> 18476.7 | AB15: =MAX(G15,Z15*H15)*E15 -> 16797
A16: =B16&C16 -> FujianShishi | B16: Fujian | C16: Shishi | D16: 86.01258 | E16: 65 | F16: 2 | G16: 450 | H16: 1.1 | I16: 华南 - 许建生 | J16: 3 | K16: 400 | L16: 0.4725 | M16: 3 | N16: 400 | O16: 0.4725 | P16: =MIN(G16,K16,N16) -> 400 | Q16: =IF(P16=K16,"蔡焱南",IF(P16=G16,"總部產品",IF(P16=K16,"蔡焱南","王峰"))) -> 蔡焱南 | R16: =MIN(H16,L16,O16) -> 0.4725 | S16: =IF(L16=R16,"蔡焱南",IF(R16=H16,"總部產品",IF(R16=L16,"蔡焱南","王峰"))) -> 蔡焱南 | T16: =ROUNDUP(G16*1.1,0) -> 495 | U16: =ROUNDUP(H16*1.1,2) -> 1.21 | W16: 0.15 | X16: =T16 -> 495 | Y16: =U16 -> 1.21 | Z16: =ROUNDUP(D16/E16*166.67,0) -> 221 | AA16: =MAX(X16,Z16*Y16)*E16 -> 32175 | AB16: =MAX(G16,Z16*H16)*E16 -> 29250
A17: =B17&C17 -> FujianXiamen | B17: Fujian | C17: Xiamen | D17: 19.488026 | E17: 8 | F17: 2 | G17: 450 | H17: 1.1 | I17: 华南 - 许建生 | J17: 3 | K17: 400 | L17: 0.4725 | M17: 3 | N17: 400 | O17: 0.4725 | P17: =MIN(G17,K17,N17) -> 400 | Q17: =IF(P17=K17,"蔡焱南",IF(P17=G17,"總部產品",IF(P17=K17,"蔡焱南","王峰"))) -> 蔡焱南 | R17: =MIN(H17,L17,O17) -> 0.4725 | S17: =IF(L17=R17,"蔡焱南",IF(R17=H17,"總部產品",IF(R17=L17,"蔡焱南","王峰"))) -> 蔡焱南 | T17: =ROUNDUP(G17*1.1,0) -> 495 | U17: =ROUNDUP(H17*1.1,2) -> 1.21 | W17: 0.15 | X17: =T17 -> 495 | Y17: =U17 -> 1.21 | Z17: =ROUNDUP(D17/E17*166.67,0) -> 407 | AA17: =MAX(X17,Z17*Y17)*E17 -> 3960 | AB17: =MAX(G17,Z17*H17)*E17 -> 3600
A18: =B18&C18 -> FujianZhangzhou | B18: Fujian | C18: Zhangzhou | D18: 105.74955 | E18: 22 | F18: 2 | G18: 450 | H18: 1.2 | I18: 华南 - 许建生 | J18: 3 | K18: 400 | L18: 0.4725 | M18: 3 | N18: 400 | O18: 0.4725 | P18: =MIN(G18,K18,N18) -> 400 | Q18: =IF(P18=K18,"蔡焱南",IF(P18=G18,"總部產品",IF(P18=K18,"蔡焱南","王峰"))) -> 蔡焱南 | R18: =MIN(H18,L18,O18) -> 0.4725 | S18: =IF(L18=R18,"蔡焱南",IF(R18=H18,"總部產品",IF(R18=L18,"蔡焱南","王峰"))) -> 蔡焱南 | T18: =ROUNDUP(G18*1.1,0) -> 495 | U18: =ROUNDUP(H18*1.1,2) -> 1.32 | W18: 0.15 | X18: =T18 -> 495 | Y18: =U18 -> 1.32 | Z18: =ROUNDUP(D18/E18*166.67,0) -> 802 | AA18: =MAX(X18,Z18*Y18)*E18 -> 23290.08 | AB18: =MAX(G18,Z18*H18)*E18 -> 21172.8
A19: =B19&C19 -> GuangdongChaozhou | B19: Guangdong | C19: Chaozhou | D19: 203.64365 | E19: 16 | F19: 3 | G19: 450 | H19: 1.2 | I19: 华南 - 许建生 | J19: 3 | K19: 400 | L19: 0.504 | M19: 4 | N19: 400 | O19: 0.504 | P19: =MIN(G19,K19,N19) -> 400 | Q19: =IF(P19=K19,"蔡焱南",IF(P19=G19,"總部產品",IF(P19=K19,"蔡焱南","王峰"))) -> 蔡焱南 | R19: =MIN(H19,L19,O19) -> 0.504 | S19: =IF(L19=R19,"蔡焱南",IF(R19=H19,"總部產品",IF(R19=L19,"蔡焱南","王峰"))) -> 蔡焱南 | T19: =ROUNDUP(G19*1.1,0) -> 495 | U19: =ROUNDUP(H19*1.1,2) -> 1.32 | W19: 0.15 | X19: =T19 -> 495 | Y19: =U19 -> 1.32 | Z19: =ROUNDUP(D19/E19*166.67,0) -> 2122 | AA19: =MAX(X19,Z19*Y19)*E19 -> 44816.64 | AB19: =MAX(G19,Z19*H19)*E19 -> 40742.4
A20: =B20&C20 -> GuangdongDongguan | B20: Guangdong | C20: Dongguan | D20: 3200.3876 | E20: 450 | F20: 3 | G20: 450 | H20: 1.2 | I20: 华南 - 许建生 | J20: 3 | K20: 400 | L20: 0.4725 | M20: 4 | N20: 400 | O20: 0.4725 | P20: =MIN(G20,K20,N20) -> 400 | Q20: =IF(P20=K20,"蔡焱南",IF(P20=G20,"總部產品",IF(P20=K20,"蔡焱南","王峰"))) -> 蔡焱南 | R20: =MIN(H20,L20,O20) -> 0.4725 | S20: =IF(L20=R20,"蔡焱南",IF(R20=H20,"總部產品",IF(R20=L20,"蔡焱南","王峰"))) -> 蔡焱南 | T20: =ROUNDUP(G20*1.1,0) -> 495 | U20: =ROUNDUP(H20*1.1,2) -> 1.32 | W20: 0.15 | X20: =T20 -> 495 | Y20: =U20 -> 1.32 | Z20: =ROUNDUP(D20/E20*166.67,0) -> 1186 | AA20: =MAX(X20,Z20*Y20)*E20 -> 704484 | AB20: =MAX(G20,Z20*H20)*E20 -> 640440
A21: =B21&C21 -> GuangdongFoshan | B21: Guangdong | C21: Foshan | D21: 13.998618 | E21: 2 | F21: 3 | G21: 450 | H21: 1.2 | I21: 华南 - 许建生 | J21: 3 | K21: 400 | L21: 0.4725 | M21: 4 | N21: 400 | O21: 0.4725 | P21: =MIN(G21,K21,N21) -> 400 | Q21: =IF(P21=K21,"蔡焱南",IF(P21=G21,"總部產品",IF(P21=K21,"蔡焱南","王峰"))) -> 蔡焱南 | R21: =MIN(H21,L21,O21) -> 0.4725 | S21: =IF(L21=R21,"蔡焱南",IF(R21=H21,"總部產品",IF(R21=L21,"蔡焱南","王峰"))) -> 蔡焱南 | T21: =ROUNDUP(G21*1.1,0) -> 495 | U21: =ROUNDUP(H21*1.1,2) -> 1.32 | W21: 0.15 | X21: =T21 -> 495 | Y21: =U21 -> 1.32 | Z21: =ROUNDUP(D21/E21*166.67,0) -> 1167 | AA21: =MAX(X21,Z21*Y21)*E21 -> 3080.88 | AB21: =MAX(G21,Z21*H21)*E21 -> 2800.8
A22: =B22&C22 -> GuangdongGuangzhou | B22: Guangdong | C22: Guangzhou | D22: 11.6629 | E22: 1 | F22: 3 | G22: 450 | H22: 1.2 | I22: 华南 - 许建生 | J22: 3 | K22: 400 | L22: 0.4725 | M22: 4 | N22: 400 | O22: 0.4725 | P22: =MIN(G22,K22,N22) -> 400 | Q22: =IF(P22=K22,"蔡焱南",IF(P22=G22,"總部產品",IF(P22=K22,"蔡焱南","王峰"))) -> 蔡焱南 | R22: =MIN(H22,L22,O22) -> 0.4725 | S22: =IF(L22=R22,"蔡焱南",IF(R22=H22,"總部產品",IF(R22=L22,"蔡焱南","王峰"))) -> 蔡焱南 | T22: =ROUNDUP(G22*1.1,0) -> 495 | U22: =ROUNDUP(H22*1.1,2) -> 1.32 | W22: 0.15 | X22: =T22 -> 495 | Y22: =U22 -> 1.32 | Z22: =ROUNDUP(D22/E22*166.67,0) -> 1944 | AA22: =MAX(X22,Z22*Y22)*E22 -> 2566.08 | AB22: =MAX(G22,Z22*H22)*E22 -> 2332.8
... A35: =B35&C35 -> GuangxiQinzhou | B35: Guangxi | C35: Qinzhou | D35: 353.70176 | E35: 38 | F35: 4 | G35: 650 | H35: 2 | I35: 华南 - 许建生 | J35: 3 | K35: 400 | L35: 0.525 | M35: 5 | N35: 400 | O35: 0.525 | P35: =MIN(G35,K35,N35) -> 400 | Q35: =IF(P35=K35,"蔡焱南",IF(P35=G35,"總部產品",IF(P35=K35,"蔡焱南","王峰"))) -> 蔡焱南 | R35: =MIN(H35,L35,O35) -> 0.525 | S35: =IF(L35=R35,"蔡焱南",IF(R35=H35,"總部產品",IF(R35=L35,"蔡焱南","王峰"))) -> 蔡焱南 | T35: =ROUNDUP(G35*1.1,0) -> 715 | U35: =ROUNDUP(H35*1.1,2) -> 2.2 | W35: 0.15 | X35: =T35 -> 715 | Y35: =U35 -> 2.2 | Z35: =ROUNDUP(D35/E35*166.67,0) -> 1552 | AA35: =MAX(X35,Z35*Y35)*E35 -> 129747.2 | AB35: =MAX(G35,Z35*H35)*E35 -> 117952
A36: =B36&C36 -> HebeiHejian | B36: Hebei | C36: Hejian | D36: 22.994218 | E36: 2 | F36: 4 | G36: 1400 | H36: =750/1000 -> 0.75 | I36: 京津-張學煜 | J36: 3 | K36: 400 | L36: 0.441 | M36: 3 | N36: 400 | O36: 0.441 | P36: =MIN(G36,K36,N36) -> 400 | Q36: =IF(P36=K36,"蔡焱南",IF(P36=G36,"總部產品",IF(P36=K36,"蔡焱南","王峰"))) -> 蔡焱南 | R36: =MIN(H36,L36,O36) -> 0.441 | S36: =IF(L36=R36,"蔡焱南",IF(R36=H36,"總部產品",IF(R36=L36,"蔡焱南","王峰"))) -> 蔡焱南 | T36: =ROUNDUP(G36*1.1,0) -> 1540 | U36: =ROUNDUP(H36*1.1,2) -> 0.83 | W36: 0.15 | X36: =T36 -> 1540 | Y36: =U36 -> 0.83 | Z36: =ROUNDUP(D36/E36*166.67,0) -> 1917 | AA36: =MAX(X36,Z36*Y36)*E36 -> 3182.22 | AB36: =MAX(G36,Z36*H36)*E36 -> 2875.5
A37: =B37&C37 -> HunanChenzhou | B37: Hunan | C37: Chenzhou | D37: 113.98778 | E37: 10 | F37: 4 | G37: 800 | H37: 1.18 | I37: 华中-王莲花 | J37: 3 | K37: 400 | L37: 0.42 | M37: 3 | N37: 400 | O37: 0.42 | P37: =MIN(G37,K37,N37) -> 400 | Q37: =IF(P37=K37,"蔡焱南",IF(P37=G37,"總部產品",IF(P37=K37,"蔡焱南","王峰"))) -> 蔡焱南 | R37: =MIN(H37,L37,O37) -> 0.42 | S37: =IF(L37=R37,"蔡焱南",IF(R37=H37,"總部產品",IF(R37=L37,"蔡焱南","王峰"))) -> 蔡焱南 | T37: =ROUNDUP(G37*1.1,0) -> 880 | U37: =ROUNDUP(H37*1.1,2) -> 1.3 | W37: 0.15 | X37: =T37 -> 880 | Y37: =U37 -> 1.3 | Z37: =ROUNDUP(D37/E37*166.67,0) -> 1900 | AA37: =MAX(X37,Z37*Y37)*E37 -> 24700 | AB37: =MAX(G37,Z37*H37)*E37 -> 22420
A38: =B38&C38 -> HunanZixing | B38: Hunan | C38: Zixing | D38: 43.40608 | E38: 4 | F38: 4 | G38: 800 | H38: 1.18 | I38: 华中-王莲花 | J38: 3 | K38: 400 | L38: 0.42 | M38: 3 | N38: 400 | O38: 0.42 | P38: =MIN(G38,K38,N38) -> 400 | Q38: =IF(P38=K38,"蔡焱南",IF(P38=G38,"總部產品",IF(P38=K38,"蔡焱南","王峰"))) -> 蔡焱南 | R38: =MIN(H38,L38,O38) -> 0.42 | S38: =IF(L38=R38,"蔡焱南",IF(R38=H38,"總部產品",IF(R38=L38,"蔡焱南","王峰"))) -> 蔡焱南 | T38: =ROUNDUP(G38*1.1,0) -> 880 | U38: =ROUNDUP(H38*1.1,2) -> 1.3 | W38: 0.15 | X38: =T38 -> 880 | Y38: =U38 -> 1.3 | Z38: =ROUNDUP(D38/E38*166.67,0) -> 1809 | AA38: =MAX(X38,Z38*Y38)*E38 -> 9406.8 | AB38: =MAX(G38,Z38*H38)*E38 -> 8538.48
A39: =B39&C39 -> JiangsuChangshu | B39: Jiangsu | C39: Changshu | D39: 0.4914 | E39: 1 | F39: 1 | G39: 200 | H39: 0.25 | I39: 华东 - 孙理想 | J39: 1 | K39: 200 | L39: 0.105 | M39: 1 | N39: 400 | O39: 0.105 | P39: =MIN(G39,K39,N39) -> 200 | Q39: =IF(P39=K39,"蔡焱南",IF(P39=G39,"總部產品",IF(P39=K39,"蔡焱南","王峰"))) -> 蔡焱南 | R39: =MIN(H39,L39,O39) -> 0.105 | S39: =IF(L39=R39,"蔡焱南",IF(R39=H39,"總部產品",IF(R39=L39,"蔡焱南","王峰"))) -> 蔡焱南 | T39: =ROUNDUP(G39*1.1,0) -> 220 | U39: =ROUNDUP(H39*1.1,2) -> 0.28 | W39: 0.15 | X39: =T39 -> 220 | Y39: =U39 -> 0.28 | Z39: =ROUNDUP(D39/E39*166.67,0) -> 82 | AA39: =MAX(X39,Z39*Y39)*E39 -> 220 | AB39: =MAX(G39,Z39*H39)*E39 -> 200
A40: =B40&C40 -> JiangsuChangzhou | B40: Jiangsu | C40: Changzhou | D40: 17.18055 | E40: 14 | F40: 1 | G40: 300 | H40: 0.28 | I40: 华东 - 孙理想 | J40: 1 | K40: 300 | L40: 0.1575 | M40: 1 | N40: 400 | O40: 0.1575 | P40: =MIN(G40,K40,N40) -> 300 | Q40: =IF(P40=K40,"蔡焱南",IF(P40=G40,"總部產品",IF(P40=K40,"蔡焱南","王峰"))) -> 蔡焱南 | R40: =MIN(H40,L40,O40) -> 0.1575 | S40: =IF(L40=R40,"蔡焱南",IF(R40=H40,"總部產品",IF(R40=L40,"蔡焱南","王峰"))) -> 蔡焱南 | T40: =ROUNDUP(G40*1.1,0) -> 330 | U40: =ROUNDUP(H40*1.1,2) -> 0.31 | W40: 0.15 | X40: =T40 -> 330 | Y40: =U40 -> 0.31 | Z40: =ROUNDUP(D40/E40*166.67,0) -> 205 | AA40: =MAX(X40,Z40*Y40)*E40 -> 4620 | AB40: =MAX(G40,Z40*H40)*E40 -> 4200
A41: =B41&C41 -> JiangsuJintan | B41: Jiangsu | C41: Jintan | D41: 0.08368 | E41: 1 | F41: 1 | G41: 300 | H41: 0.28 | I41: 华东 - 孙理想 | J41: 1 | K41: 300 | L41: 0.1575 | M41: 1 | N41: 400 | O41: 0.1575 | P41: =MIN(G41,K41,N41) -> 300 | Q41: =IF(P41=K41,"蔡焱南",IF(P41=G41,"總部產品",IF(P41=K41,"蔡焱南","王峰"))) -> 蔡焱南 | R41: =MIN(H41,L41,O41) -> 0.1575 | S41: =IF(L41=R41,"蔡焱南",IF(R41=H41,"總部產品",IF(R41=L41,"蔡焱南","王峰"))) -> 蔡焱南 | T41: =ROUNDUP(G41*1.1,0) -> 330 | U41: =ROUNDUP(H41*1.1,2) -> 0.31 | W41: 0.15 | X41: =T41 -> 330 | Y41: =U41 -> 0.31 | Z41: =ROUNDUP(D41/E41*166.67,0) -> 14 | AA41: =MAX(X41,Z41*Y41)*E41 -> 330 | AB41: =MAX(G41,Z41*H41)*E41 -> 300
A42: =B42&C42 -> JiangsuLianyungang | B42: Jiangsu | C42: Lianyungang | D42: 129.58944 | E42: 15 | F42: 2 | G42: 600 | H42: 0.42 | I42: 华东 - 孙理想 | J42: 1 | K42: 300 | L42: 0.21 | M42: 2 | N42: 400 | O42: 0.21 | P42: =MIN(G42,K42,N42) -> 300 | Q42: =IF(P42=K42,"蔡焱南",IF(P42=G42,"總部產品",IF(P42=K42,"蔡焱南","王峰"))) -> 蔡焱南 | R42: =MIN(H42,L42,O42) -> 0.21 | S42: =IF(L42=R42,"蔡焱南",IF(R42=H42,"總部產品",IF(R42=L42,"蔡焱南","王峰"))) -> 蔡焱南 | T42: =ROUNDUP(G42*1.1,0) -> 660 | U42: =ROUNDUP(H42*1.1,2) -> 0.47 | W42: 0.15 | X42: =T42 -> 660 | Y42: =U42 -> 0.47 | Z42: =ROUNDUP(D42/E42*166.67,0) -> 1440 | AA42: =MAX(X42,Z42*Y42)*E42 -> 10152 | AB42: =MAX(G42,Z42*H42)*E42 -> 9072
A43: =B43&C43 -> JiangsuSuzhou | B43: Jiangsu | C43: Suzhou | D43: 162.0281 | E43: 20 | F43: 1 | G43: 300 | H43: 0.25 | I43: 华东 - 孙理想 | J43: 1 | K43: 300 | L43: 0.1575 | M43: 1 | N43: 400 | O43: 0.1575 | P43: =MIN(G43,K43,N43) -> 300 | Q43: =IF(P43=K43,"蔡焱南",IF(P43=G43,"總部產品",IF(P43=K43,"蔡焱南","王峰"))) -> 蔡焱南 | R43: =MIN(H43,L43,O43) -> 0.1575 | S43: =IF(L43=R43,"蔡焱南",IF(R43=H43,"總部產品",IF(R43=L43,"蔡焱南","王峰"))) -> 蔡焱南 | T43: =ROUNDUP(G43*1.1,0) -> 330 | U43: =ROUNDUP(H43*1.1,2) -> 0.28 | W43: 0.15 | X43: =T43 -> 330 | Y43: =U43 -> 0.28 | Z43: =ROUNDUP(D43/E43*166.67,0) -> 1351 | AA43: =MAX(X43,Z43*Y43)*E43 -> 7565.6 | AB43: =MAX(G43,Z43*H43)*E43 -> 6755
A44: =B44&C44 -> JiangsuWuxi | B44: Jiangsu | C44: Wuxi | D44: 7.60442 | E44: 2 | F44: 1 | G44: 300 | H44: 0.3 | I44: 华东 - 孙理想 | J44: 1 | K44: 300 | L44: 0.1575 | M44: 1 | N44: 400 | O44: 0.1575 | P44: =MIN(G44,K44,N44) -> 300 | Q44: =IF(P44=K44,"蔡焱南",IF(P44=G44,"總部產品",IF(P44=K44,"蔡焱南","王峰"))) -> 蔡焱南 | R44: =MIN(H44,L44,O44) -> 0.1575 | S44: =IF(L44=R44,"蔡焱南",IF(R44=H44,"總部產品",IF(R44=L44,"蔡焱南","王峰"))) -> 蔡焱南 | T44: =ROUNDUP(G44*1.1,0) -> 330 | U44: =ROUNDUP(H44*1.1,2) -> 0.33 | W44: 0.15 | X44: =T44 -> 330 | Y44: =U44 -> 0.33 | Z44: =ROUNDUP(D44/E44*166.67,0) -> 634 | AA44: =MAX(X44,Z44*Y44)*E44 -> 660 | AB44: =MAX(G44,Z44*H44)*E44 -> 600
A45: =B45&C45 -> JiangsuYangzhou | B45: Jiangsu | C45: Yangzhou | D45: 10.05849 | E45: 1 | F45: 1 | G45: 300 | H45: 0.33 | I45: 华东 - 孙理想 | J45: 1 | K45: 300 | L45: 0.1575 | M45: 1 | N45: 400 | O45: 0.1575 | P45: =MIN(G45,K45,N45) -> 300 | Q45: =IF(P45=K45,"蔡焱南",IF(P45=G45,"總部產品",IF(P45=K45,"蔡焱南","王峰"))) -> 蔡焱南 | R45: =MIN(H45,L45,O45) -> 0.1575 | S45: =IF(L45=R45,"蔡焱南",IF(R45=H45,"總部產品",IF(R45=L45,"蔡焱南","王峰"))) -> 蔡焱南 | T45: =ROUNDUP(G45*1.1,0) -> 330 | U45: =ROUNDUP(H45*1.1,2) -> 0.37 | W45: 0.15 | X45: =T45 -> 330 | Y45: =U45 -> 0.37 | Z45: =ROUNDUP(D45/E45*166.67,0) -> 1677 | AA45: =MAX(X45,Z45*Y45)*E45 -> 620.49 | AB45: =MAX(G45,Z45*H45)*E45 -> 553.41
A46: =B46&C46 -> JiangxiGanzhou | B46: Jiangxi | C46: Ganzhou | D46: 447.35568 | E46: 50 | F46: 4 | G46: 800 | H46: 1.18 | I46: 华中-王莲花 | J46: 3 | K46: 300 | L46: 0.399 | M46: 3 | N46: 400 | O46: 0.399 | P46: =MIN(G46,K46,N46) -> 300 | Q46: =IF(P46=K46,"蔡焱南",IF(P46=G46,"總部產品",IF(P46=K46,"蔡焱南","王峰"))) -> 蔡焱南 | R46: =MIN(H46,L46,O46) -> 0.399 | S46: =IF(L46=R46,"蔡焱南",IF(R46=H46,"總部產品",IF(R46=L46,"蔡焱南","王峰"))) -> 蔡焱南 | T46: =ROUNDUP(G46*1.1,0) -> 880 | U46: =ROUNDUP(H46*1.1,2) -> 1.3 | W46: 0.15 | X46: =T46 -> 880 | Y46: =U46 -> 1.3 | Z46: =ROUNDUP(D46/E46*166.67,0) -> 1492 | AA46: =MAX(X46,Z46*Y46)*E46 -> 96980 | AB46: =MAX(G46,Z46*H46)*E46 -> 88028
A47: =B47&C47 -> ShandongQingdao | B47: Shandong | C47: Qingdao | D47: 316.67765 | E47: 67 | F47: 3 | G47: 800 | H47: 0.7 | I47: 京津-張學煜 | J47: 3 | K47: 300 | L47: 0.42 | M47: 3 | N47: 400 | O47: 0.42 | P47: =MIN(G47,K47,N47) -> 300 | Q47: =IF(P47=K47,"蔡焱南",IF(P47=G47,"總部產品",IF(P47=K47,"蔡焱南","王峰"))) -> 蔡焱南 | R47: =MIN(H47,L47,O47) -> 0.42 | S47: =IF(L47=R47,"蔡焱南",IF(R47=H47,"總部產品",IF(R47=L47,"蔡焱南","王峰"))) -> 蔡焱南 | T47: =ROUNDUP(G47*1.1,0) -> 880 | U47: =ROUNDUP(H47*1.1,2) -> 0.77 | W47: 0.15 | X47: =T47 -> 880 | Y47: =U47 -> 0.77 | Z47: =ROUNDUP(D47/E47*166.67,0) -> 788 | AA47: =MAX(X47,Z47*Y47)*E47 -> 58960 | AB47: =MAX(G47,Z47*H47)*E47 -> 53600
A48: =B48&C48 -> ShandongRizhao | B48: Shandong | C48: Rizhao | D48: 92.326598 | E48: 25 | F48: 3 | G48: 800 | H48: 0.6 | I48: 京津-張學煜 | J48: 3 | K48: 300 | L48: 0.42 | M48: 3 | N48: 400 | O48: 0.42 | P48: =MIN(G48,K48,N48) -> 300 | Q48: =IF(P48=K48,"蔡焱南",IF(P48=G48,"總部產品",IF(P48=K48,"蔡焱南","王峰"))) -> 蔡焱南 | R48: =MIN(H48,L48,O48) -> 0.42 | S48: =IF(L48=R48,"蔡焱南",IF(R48=H48,"總部產品",IF(R48=L48,"蔡焱南","王峰"))) -> 蔡焱南 | T48: =ROUNDUP(G48*1.1,0) -> 880 | U48: =ROUNDUP(H48*1.1,2) -> 0.66 | W48: 0.15 | X48: =T48 -> 880 | Y48: =U48 -> 0.66 | Z48: =ROUNDUP(D48/E48*166.67,0) -> 616 | AA48: =MAX(X48,Z48*Y48)*E48 -> 22000 | AB48: =MAX(G48,Z48*H48)*E48 -> 20000
... A60: =B60&C60 -> ZhejiangTaizhou | B60: Zhejiang | C60: Taizhou | D60: 0.6084 | E60: 1 | F60: 2 | G60: 600 | H60: 0.42 | I60: 华东 - 孙理想 | J60: 2 | K60: 300 | L60: 0.231 | M60: 1 | N60: 400 | O60: 0.231 | P60: =MIN(G60,K60,N60) -> 300 | Q60: =IF(P60=K60,"蔡焱南",IF(P60=G60,"總部產品",IF(P60=K60,"蔡焱南","王峰"))) -> 蔡焱南 | R60: =MIN(H60,L60,O60) -> 0.231 | S60: =IF(L60=R60,"蔡焱南",IF(R60=H60,"總部產品",IF(R60=L60,"蔡焱南","王峰"))) -> 蔡焱南 | T60: =ROUNDUP(G60*1.1,0) -> 660 | U60: =ROUNDUP(H60*1.1,2) -> 0.47 | W60: 0.15 | X60: =T60 -> 660 | Y60: =U60 -> 0.47 | Z60: =ROUNDUP(D60/E60*166.67,0) -> 102 | AA60: =MAX(X60,Z60*Y60)*E60 -> 660 | AB60: =MAX(G60,Z60*H60)*E60 -> 600
A61: =B61&C61 -> BeihaiGuangxi | B61: Beihai | C61: Guangxi | F61: 4 | G61: 650 | H61: 2.8 | I61: 华南 - 许建生 | J61: 3 | K61: 400 | L61: 0.525 | M61: 5 | N61: 400 | O61: 0.525 | P61: =MIN(G61,K61,N61) -> 400 | Q61: =IF(P61=K61,"蔡焱南",IF(P61=G61,"總部產品",IF(P61=K61,"蔡焱南","王峰"))) -> 蔡焱南 | R61: =MIN(H61,L61,O61) -> 0.525 | S61: =IF(L61=R61,"蔡焱南",IF(R61=H61,"總部產品",IF(R61=L61,"蔡焱南","王峰"))) -> 蔡焱南 | T61: =ROUNDUP(G61*1.1,0) -> 715 | U61: =ROUNDUP(H61*1.1,2) -> 3.08 | W61: 0.15 | X61: =T61 -> 715 | Y61: =U61 -> 3.08 | Z61: 0 | AA61: =MAX(X61,Z61*Y61)*E61 -> 0 | AB61: =MAX(G61,Z61*H61)*E61 -> 0
A62: =B62&C62 -> WenzhouZhejiang | B62: Wenzhou | C62: Zhejiang | F62: 2 | G62: 600 | H62: 0.42 | I62: 华东 - 孙理想 | J62: 2 | K62: 300 | L62: 0.3675 | M62: 1 | N62: 400 | O62: 0.3675 | P62: =MIN(G62,K62,N62) -> 300 | Q62: =IF(P62=K62,"蔡焱南",IF(P62=G62,"總部產品",IF(P62=K62,"蔡焱南","王峰"))) -> 蔡焱南 | R62: =MIN(H62,L62,O62) -> 0.3675 | S62: =IF(L62=R62,"蔡焱南",IF(R62=H62,"總部產品",IF(R62=L62,"蔡焱南","王峰"))) -> 蔡焱南 | T62: =ROUNDUP(G62*1.1,0) -> 660 | U62: =ROUNDUP(H62*1.1,2) -> 0.47 | W62: 0.15 | X62: =T62 -> 660 | Y62: =U62 -> 0.47 | Z62: 0 | AA62: =MAX(X62,Z62*Y62)*E62 -> 0 | AB62: =MAX(G62,Z62*H62)*E62 -> 0

Sheet Domestic Ocean
B1: DOMESTIC OCEAN RATE
B3: ORIGIN: Guangdong, China
B4: Destinations
B5: SHDR DC1(Main DC):上海临港新城普洛斯临港物流园洋浩路575号 No.575 Yanghao Road, Pudong New District, Shanghai, China
B6: TDSC DC:上海市奉贤区航塘公路3088号C栋3楼DISNEY STORE WAREHOUSE,KERRYEAS SHANGHAI DISTRIBUTION CENTER C3,3088 HANGTANG HIGHWAY,FENGXIAN DISTRICT, SHANGHAI
B7: Currency :RMB
G8: SHDR DC1/TDSC DC | L8: 利潤 | M8: 0.2
E9: Historical Shipping Volume (cbm) | G9: Transit time(days, pickup date is excluded) | H9: Quotation | L9: AR | N9: 預計貨量
B10: Cost Items | C10: Currency | D10: UOM | E10: 20GP | F10: 40'/40HQ | G10: Transit | H10: 20GP | I10: 40'/40HQ | L10: 20'GP | M10: 40'GP/HQ | N10: 20'GP | O10: 40'GP/HQ | P10: 預計營收 | Q10: 預計成本
B11: All-in Door-to-Door Rate from Dongguan | C11: CNY | D11: per container size | E11: 58.2075 | F11: 759.55 | G11: 6 days(船运时间，不含提派时间） | H11: 6550 | I11: 7380 | J11: 产品归属周天真 | L11: =ROUNDUP(H11*(1+$M$8),0) -> 7860 | M11: =ROUNDUP(I11*(1+$M$8),0) -> 8856 | N11: =ROUNDDOWN(E11/25,0) -> 2 | O11: =ROUNDDOWN(F11/65,0) -> 11 | P11: =N11*L11+O11*M11 -> 113136 | Q11: =H11*N11+I11*O11 -> 94280
B13: Other | C13: Response
B14: Sailing Schedule | C14: 1 sailing per week
B15: Underlying Carriers | C15: no info
B16: Transit Days | C16: 10-11days(waiting time excluded)
B17: Origin / Destination terminals | C17: DONGGUAN/SHANGHAI
B18: Temp. Monitoring Device for Reefer Containers | C18: Reefer container to be quoted separately.
B20: Demurrage (Storage of containers at port) | C20: Carrier Proposed
B21: Rate (RMB) per day, after free time expires | C21: 上海：第8-10天： 小柜每天20 /大柜每天40 第11天后： 小柜每天70/ 大柜每天140 第11天后 小柜收取50一柜的平移费 大柜收取75一柜的平移费 东莞：第8-14天 小柜每天12/ 大柜每天24 第15-21天 小柜每天18 大柜每天36 22天后 小柜每天24 大柜每天48
B22: Free Time: Days before demurrage begins | C22: 7 calendar days free demurrage
B25: Detention (Storage of containers in customer care) | C25: Carrier Proposed
B26: Rate (RMB) per day, after free time expires | C26: 第8-14天： 小柜每天63/ 大柜每天130 第15-21天： 小柜每天126/ 大柜每天260 22天后： 小柜每天189 /大柜每天390
B27: Free Time: Days before detention begins | C27: 7 calendar days free detention

Sheet FTL volume (customer provided)
A1: FTL Truck Type | C1: Provice | D1: City | E1: Sum of No. of shipment | F1: Sum of 2027 Projected vol | G1: 省份 | H1: 城市 | I1: 每車體積 | J1: 車型
A2: Truck | B2: =C2&D2&J2 -> AnhuiChaohu26T | C2: Anhui | D2: Chaohu | E2: 328 | F2: 31716.44 | G2: 安徽 | H2: 巢湖 | I2: 97 | J2: 26T
A3: Truck | B3: =C3&D3&J3 -> AnhuiTianchang25T | C3: Anhui | D3: Tianchang | E3: 127 | F3: 10547.85 | G3: 安徽 | H3: 天长 | I3: 84 | J3: 25T
A4: Truck | B4: =C4&D4&J4 -> AnhuiXuancheng15T | C4: Anhui | D4: Xuancheng | E4: 12 | F4: 653.91 | G4: 安徽 | H4: 宣城 | I4: 55 | J4: 15T
A5: Truck | B5: =C5&D5&J5 -> FujianQuanzhou25T | C5: Fujian | D5: Quanzhou | E5: 35 | F5: 2647.32 | G5: 福建 | H5: 泉州 | I5: 76 | J5: 25T
A6: Truck | B6: =C6&D6&J6 -> FujianShishi5T | C6: Fujian | D6: Shishi | E6: 4 | F6: 56.22 | G6: 福建 | H6: 石狮 | I6: 15 | J6: 5T
A7: Truck | B7: =C7&D7&J7 -> GuangdongDongguan25T | C7: Guangdong | D7: Dongguan | E7: 157 | F7: 12436.51 | G7: 广东 | H7: 东莞 | I7: 80 | J7: 25T
A8: Truck | B8: =C8&D8&J8 -> GuangdongFoshan5T | C8: Guangdong | D8: Foshan | E8: 2 | F8: 31.3 | G8: 广东 | H8: 佛山 | I8: 16 | J8: 5T
A9: Truck | B9: =C9&D9&J9 -> GuangdongHeyuan3T | C9: Guangdong | D9: Heyuan | E9: 7 | F9: 21.27 | G9: 广东 | H9: 河源 | I9: 4 | J9: 3T
A10: Truck | B10: =C10&D10&J10 -> GuangdongHuizhou20’GP | C10: Guangdong | D10: Huizhou | E10: 23 | F10: 587.91 | G10: 广东 | H10: 惠州 | I10: 26 | J10: 20’GP
A11: Truck | B11: =C11&D11&J11 -> GuangdongJiangmen3T | C11: Guangdong | D11: Jiangmen | E11: 1 | F11: 8.03 | G11: 广东 | H11: 江门 | I11: 9 | J11: 3T
A12: Truck | B12: =C12&D12&J12 -> GuangdongShantou20’GP | C12: Guangdong | D12: Shantou | E12: 3 | F12: 69.41 | G12: 广东 | H12: 汕头 | I12: 24 | J12: 20’GP
A13: Truck | B13: =C13&D13&J13 -> GuangdongShenzhen25T | C13: Guangdong | D13: Shenzhen | E13: 38 | F13: 2911.3 | G13: 广东 | H13: 深圳 | I13: 77 | J13: 25T
... A37: Truck | B37: =C37&D37&J37 -> ZhejiangPinghu5T | C37: Zhejiang | D37: Pinghu | E37: 12 | F37: 173.92 | G37: 浙江 | H37: 平湖 | I37: 15 | J37: 5T
A38: Truck-DG | C38: Guangdong | D38: Dongguan | E38: 6 | F38: 40.8 | G38: 广东 | H38: 东莞 | I38: 7 | J38: 3T
A39: Truck-REF | C39: Guangdong | D39: Dongguan | E39: 2 | F39: 16.17 | G39: 广东 | H39: 东莞 | I39: 9 | J39: 3T
A40: Truck-REF | C40: Guangdong | D40: Foshan | E40: 3 | F40: 42.93 | G40: 广东 | H40: 佛山 | I40: 15 | J40: 5T
A41: Truck-REF | C41: Guangdong | D41: Shantou | E41: 24 | F41: 196.15 | G41: 广东 | H41: 汕头 | I41: 9 | J41: 3T
A42: Truck-REF | C42: Jiangxi | D42: Nanchang | E42: 1 | F42: 54.39 | G42: 江西 | H42: 南昌 | I42: 55 | J42: 15T
A43: Truck-REF | C43: Shanghai | D43: Shanghai | E43: 14 | F43: 106.34 | G43: 上海 | H43: 上海 | I43: 8 | J43: 3T
A44: Truck-SOC | B44: =C44&D44&J44 -> AnhuiChaohu40'HQ | C44: Anhui | D44: Chaohu | E44: 20 | F44: 1246.46 | G44: 安徽 | H44: 巢湖 | I44: 63 | J44: 40'HQ
A45: Truck-SOC | B45: =C45&D45&J45 -> AnhuiTianchang15T | C45: Anhui | D45: Tianchang | E45: 7 | F45: 367.4 | G45: 安徽 | H45: 天长 | I45: 53 | J45: 15T
A46: Truck-SOC | B46: =C46&D46&J46 -> FujianQuanzhou40'HQ | C46: Fujian | D46: Quanzhou | E46: 5 | F46: 308.32 | G46: 福建 | H46: 泉州 | I46: 62 | J46: 40'HQ
A47: Truck-SOC | B47: =C47&D47&J47 -> GuangdongDongguan40'HQ | C47: Guangdong | D47: Dongguan | E47: 15 | F47: 889.36 | G47: 广东 | H47: 东莞 | I47: 60 | J47: 40'HQ
A48: Truck-SOC | B48: =C48&D48&J48 -> GuangdongHuizhou12T | C48: Guangdong | D48: Huizhou | E48: 1 | F48: 42.17 | G48: 广东 | H48: 惠州 | I48: 43 | J48: 12T
A49: Truck-SOC | B49: =C49&D49&J49 -> GuangdongShantou40'HQ | C49: Guangdong | D49: Shantou | E49: 1 | F49: 62.11 | G49: 广东 | H49: 汕头 | I49: 63 | J49: 40'HQ
A50: Truck-SOC | B50: =C50&D50&J50 -> GuangdongShenzhen12T | C50: Guangdong | D50: Shenzhen | E50: 3 | F50: 129.39 | G50: 广东 | H50: 深圳 | I50: 44 | J50: 12T
A51: Truck-SOC | B51: =C51&D51&J51 -> GuangdongZhongshan40'HQ | C51: Guangdong | D51: Zhongshan | E51: 1 | F51: 64.34 | G51: 广东 | H51: 中山 | I51: 65 | J51: 40'HQ
A52: Truck-SOC | B52: =C52&D52&J52 -> GuangdongZhuhai5T | C52: Guangdong | D52: Zhuhai | E52: 1 | F52: 18.22 | G52: 广东 | H52: 珠海 | I52: 19 | J52: 5T
A53: Truck-SOC | B53: =C53&D53&J53 -> GuangxiPubei25T | C53: Guangxi | D53: Pubei | E53: 2 | F53: 138.16 | G53: 广西 | H53: 浦北 | I53: 70 | J53: 25T
A54: Truck-SOC | B54: =C54&D54&J54 -> GuangxiQinzhou40'HQ | C54: Guangxi | D54: Qinzhou | E54: 17 | F54: 948.98 | G54: 广西 | H54: 钦州 | I54: 56 | J54: 40'HQ
A55: Truck-SOC | B55: =C55&D55&J55 -> HebeiHejian40'HQ | C55: Hebei | D55: Hejian | E55: 1 | F55: 66.87 | G55: 河北 | H55: 河间 | I55: 67 | J55: 40'HQ
... A59: Truck-SOC | B59: =C59&D59&J59 -> ZhejiangHuzhou15T | C59: Zhejiang | D59: Huzhou | E59: 4 | F59: 183.24 | G59: 浙江 | H59: 湖州 | I59: 46 | J59: 15T

Sheet 供應商0827 - 1200更新線路報價
B1: FULL TRUCK RATES
B2: Rates to be awarded by MOT. Rates submitted must not be contingent upon bundled award.
B4: Destinations
B5: SHDR DC1(Main DC):上海临港新城普洛斯临港物流园洋浩路575号 No.575 Yanghao Road, Pudong New District, Shanghai, China
B6: TDSC DC:上海市奉贤区航塘公路3088号C栋3楼DISNEY STORE WAREHOUSE,KERRYEAS SHANGHAI DISTRIBUTION CENTER C3,3088 HANGTANG HIGHWAY,FENGXIAN DISTRICT, SHANGHAI
B7: Currency :RMB | C7: Exclude VAT
F9: SHDR DC1/TDSC DC | G9: 原報價 | I9: 目標價
B10: From Province | C10: From City | D10: Lorry Size | E10: Temperature | F10: SHDR DC1/TDSC DC | G10: Rate (RMB) Excluding VAT | H10: 新报价 | I10: Rate (RMB) Excluding VAT
A11: =B11&C11&D11&E11 -> ShanxiAnkang5TDRY | B11: Shanxi | C11: Ankang | D11: 5T | E11: DRY | F11: 2 | G11: 5955 | H11: =G11 -> 5955 | I11: 4800
A12: =B12&C12&D12&E12 -> ShanxiAnkang20'GPDRY - SOC | B12: Shanxi | C12: Ankang | D12: 20'GP | E12: DRY - SOC | F12: 2 | G12: 6065 | H12: =G12 -> 6065 | I12: 5040
A13: =B13&C13&D13&E13 -> ShanxiAnkang40'HQDRY - SOC | B13: Shanxi | C13: Ankang | D13: 40'HQ | E13: DRY - SOC | F13: 2 | G13: 10040 | H13: 9450 | I13: 8400
A14: =B14&C14&D14&E14 -> ShanxiAnkang15TDRY | B14: Shanxi | C14: Ankang | D14: 15T | E14: DRY | F14: 2 | G14: 7390 | H14: =G14 -> 7390 | I14: 7200
A15: =B15&C15&D15&E15 -> ShanxiAnkang26TDRY | B15: Shanxi | C15: Ankang | D15: 26T | E15: DRY | F15: 2 | G15: 10040 | H15: =G15 -> 10040 | I15: 9600
A16: =B16&C16&D16&E16 -> ShanxiAnkang3TDRY | B16: Shanxi | C16: Ankang | D16: 3T | E16: DRY | F16: 2 | G16: 3310 | H16: =G16 -> 3310 | I16: 3150
A17: =B17&C17&D17&E17 -> ShanxiAnkang8TDRY | B17: Shanxi | C17: Ankang | D17: 8T | E17: DRY | F17: 2 | G17: 5955 | H17: =G17 -> 5955 | I17: 5040
A18: =B18&C18&D18&E18 -> ShanxiAnkang10TDRY | B18: Shanxi | C18: Ankang | D18: 10T | E18: DRY | F18: 2 | G18: 6065 | H18: =G18 -> 6065 | I18: 5280
A19: =B19&C19&D19&E19 -> ShanxiAnkang12TDRY | B19: Shanxi | C19: Ankang | D19: 12T | E19: DRY | F19: 2 | G19: 6290 | H19: 5985 | I19: 5520
A20: =B20&C20&D20&E20 -> ShanxiAnkang25TDRY | B20: Shanxi | C20: Ankang | D20: 25T | E20: DRY | F20: 2 | G20: 9925 | H20: =G20 -> 9925 | I20: 8800
A21: =B21&C21&D21&E21 -> GuangxiBeihai26TDRY | B21: Guangxi | C21: Beihai | D21: 26T | E21: DRY | G21: 9045 | H21: =G21 -> 9045 | I21: 8560
A22: =B22&C22&D22&E22 -> GuangxiBeihai10TDRY | B22: Guangxi | C22: Beihai | D22: 10T | E22: DRY | G22: 6290 | H22: =G22 -> 6290 | I22: 5840
A23: =B23&C23&D23&E23 -> GuangxiBeihai12TDRY | B23: Guangxi | C23: Beihai | D23: 12T | E23: DRY | G23: 6510 | H23: =G23 -> 6510 | I23: 5920
A24: =B24&C24&D24&E24 -> GuangxiBeihai15TDRY | B24: Guangxi | C24: Beihai | D24: 15T | E24: DRY | G24: 6615 | H24: =G24 -> 6615 | I24: 6000
A25: =B25&C25&D25&E25 -> GuangxiBeihai25TDRY | B25: Guangxi | C25: Beihai | D25: 25T | E25: DRY | G25: 8820 | H25: =G25 -> 8820 | I25: 8000
A26: =B26&C26&D26&E26 -> GuangxiBeihai40'HQDRY - SOC | B26: Guangxi | C26: Beihai | D26: 40'HQ | E26: DRY - SOC | G26: 8820 | H26: =G26 -> 8820 | I26: 7520
A27: =B27&C27&D27&E27 -> GuangxiBeihai20'GPDRY - SOC | B27: Guangxi | C27: Beihai | D27: 20'GP | E27: DRY - SOC | G27: 6290 | H27: =G27 -> 6290 | I27: 5325
A28: =B28&C28&D28&E28 -> GuangxiBeihai3TDRY | B28: Guangxi | C28: Beihai | D28: 3T | E28: DRY | G28: 4085 | H28: =G28 -> 4085 | I28: 4000
A29: =B29&C29&D29&E29 -> GuangxiBeihai5TDRY | B29: Guangxi | C29: Beihai | D29: 5T | E29: DRY | G29: 5405 | H29: =G29 -> 5405 | I29: 5250
A30: =B30&C30&D30&E30 -> GuangxiBeihai8TDRY | B30: Guangxi | C30: Beihai | D30: 8T | E30: DRY | G30: 5515 | H30: =G30 -> 5515 | I30: 5325
A31: =B31&C31&D31&E31 -> JiangsuChangzhou20'GPDRY - SOC | B31: Jiangsu | C31: Changzhou | D31: 20'GP | E31: DRY - SOC | F31: 1 | G31: 1545 | H31: 1260 | I31: 1200
A32: =B32&C32&D32&E32 -> JiangsuChangzhou10TDRY | B32: Jiangsu | C32: Changzhou | D32: 10T | E32: DRY | F32: 1 | G32: 1545 | H32: 1333.5 | I32: 1240
A33: =B33&C33&D33&E33 -> JiangsuChangzhou8TDRY | B33: Jiangsu | C33: Changzhou | D33: 8T | E33: DRY | F33: 1 | G33: 1440 | H33: 1260 | I33: 1200
A34: =B34&C34&D34&E34 -> JiangsuChangzhou25TDRY | B34: Jiangsu | C34: Changzhou | D34: 25T | E34: DRY | F34: 1 | G34: 2205 | H34: =G34 -> 2205 | I34: 1850
A35: =B35&C35&D35&E35 -> JiangsuChangzhou26TDRY | B35: Jiangsu | C35: Changzhou | D35: 26T | E35: DRY | F35: 1 | G35: 2320 | H35: 2047.5 | I35: 1950
A36: =B36&C36&D36&E36 -> JiangsuChangzhou3TDRY | B36: Jiangsu | C36: Changzhou | D36: 3T | E36: DRY | F36: 1 | G36: 845 | H36: 787.5 | I36: 720
A37: =B37&C37&D37&E37 -> JiangsuChangzhou12TDRY | B37: Jiangsu | C37: Changzhou | D37: 12T | E37: DRY | F37: 1 | G37: 1655 | H37: =G37 -> 1655 | I37: 1650
A38: =B38&C38&D38&E38 -> JiangsuChangzhou15TDRY | B38: Jiangsu | C38: Changzhou | D38: 15T | E38: DRY | F38: 1 | G38: 1770 | H38: =G38 -> 1770 | I38: 1750
A39: =B39&C39&D39&E39 -> JiangsuChangzhou40'HQDRY - SOC | B39: Jiangsu | C39: Changzhou | D39: 40'HQ | E39: DRY - SOC | F39: 1 | G39: 2205 | H39: 2047.5 | I39: 1920
A40: =B40&C40&D40&E40 -> JiangsuChangzhou5TDRY | B40: Jiangsu | C40: Changzhou | D40: 5T | E40: DRY | F40: 1 | G40: 1330 | H40: =G40 -> 1330 | I40: 1160
A41: =B41&C41&D41&E41 -> AnhuiChaohu3TDRY | B41: Anhui | C41: Chaohu | D41: 3T | E41: DRY | F41: 1 | G41: 1220 | H41: =G41 -> 1220 | I41: 1160
A42: =B42&C42&D42&E42 -> AnhuiChaohu40'HQDRY - SOC | B42: Anhui | C42: Chaohu | D42: 40'HQ | E42: DRY - SOC | F42: 1 | G42: 3860 | H42: =G42 -> 3860 | I42: 3750
...
